Workbook

Sheet Palmares
B3: Liga
B4: 2018 | C4: Juan Ramon Perez
B5: 2019 | C5: Juan Ramon Perez
B6: 2020 apertura | C6: Chema Martínez
B7: 2020 clausura | C7: Chema Martínez
B8: 2021 Apertura | C8: Chema Martínez
B9: 2021 Clausura | C9: Juan Ramon Perez | D9: Copa
B10: 2022 | C10: Juan Ramon Perez | D10: 2021 | E10: Chema Martínez
B11: 2023 | C11: Alberto Salazar | D11: 2022 | E11: Chema Martínez
B12: 2024 Apertura | C12: Jorge Santiago | D12: 2023 | E12: Alberto Salazar
B13: 2024 Clausura | C13: Jorge Santiago | D13: 2024 | E13: Chema Martínez
B14: 2025 | C14: Jorge Santiago | D14: 2025 | E14: Jorge Santiago

Sheet Semilla Liga Plata
B3: SEMILLERO LIGA PLATA
B5: Posicion | C5: FOOTGOLFER NICKNAME | D5: Etapa 1 | E5: Etapa 2 | F5: Etapa 3 | G5: Etapa 4 | H5: Etapa 5 | I5: Etapa 6 | J5: Etapa 7 | K5: Etapa 8 | L5: Etapa 9 | M5: Etapa 10 | N5: Total | O5: Maximos puntos posibles
B6: =ROW() - ROW($B$6) + 1 -> 1 | C6: Jorge Santiago Buqueras | D6: 250 | E6: =IFERROR(VLOOKUP($C6,'Etapa 2 Masculina'!$E$3:$G$100,3,FALSE),0) -> 250 | F6: =IFERROR(VLOOKUP($C6,'Etapa 3 Absoluta'!$E$3:$G$98,3,FALSE),0) -> 250 | G6: =IFERROR(VLOOKUP($C6,'Etapa 4 Absoluta'!$E$3:$G$98,3,FALSE),0) -> 230 | H6: =IFERROR(VLOOKUP($C6,'Etapa 5 Absoluta'!$E$3:$G$98,3,FALSE),0) -> 250 | I6: 0 | J6: 0 | K6: 0 | L6: 0 | M6: 0 | N6: {=SUM(LARGE(D6:M6,{1;2;3}))} -> 750
B7: =ROW() - ROW($B$6) + 1 -> 2 | C7: Olivier TRESSENS | D7: 230 | E7: =IFERROR(VLOOKUP($C7,'Etapa 2 Masculina'!$E$3:$G$100,3,FALSE),0) -> 215 | F7: =IFERROR(VLOOKUP($C7,'Etapa 3 Absoluta'!$E$3:$G$98,3,FALSE),0) -> 215 | G7: =IFERROR(VLOOKUP($C7,'Etapa 4 Absoluta'!$E$3:$G$98,3,FALSE),0) -> 170 | H7: =IFERROR(VLOOKUP($C7,'Etapa 5 Absoluta'!$E$3:$G$98,3,FALSE),0) -> 215 | I7: 0 | J7: 0 | K7: 0 | L7: 0 | M7: 0 | N7: {=SUM(LARGE(D7:M7,{1;2;3}))} -> 660
B8: =ROW() - ROW($B$6) + 1 -> 3 | C8: Alberto Salazar Fernández | D8: 215 | E8: =IFERROR(VLOOKUP($C8,'Etapa 2 Masculina'!$E$3:$G$100,3,FALSE),0) -> 0 | F8: =IFERROR(VLOOKUP($C8,'Etapa 3 Absoluta'!$E$3:$G$98,3,FALSE),0) -> 0 | G8: =IFERROR(VLOOKUP($C8,'Etapa 4 Absoluta'!$E$3:$G$98,3,FALSE),0) -> 250 | H8: =IFERROR(VLOOKUP($C8,'Etapa 5 Absoluta'!$E$3:$G$98,3,FALSE),0) -> 200 | I8: 0 | J8: 0 | K8: 0 | L8: 0 | M8: 0 | N8: {=SUM(LARGE(D8:M8,{1;2;3}))} -> 665
B9: =ROW() - ROW($B$6) + 1 -> 4 | C9: JuanRa Perez | D9: 110 | E9: =IFERROR(VLOOKUP($C9,'Etapa 2 Masculina'!$E$3:$G$100,3,FALSE),0) -> 180 | F9: =IFERROR(VLOOKUP($C9,'Etapa 3 Absoluta'!$E$3:$G$98,3,FALSE),0) -> 200 | G9: =IFERROR(VLOOKUP($C9,'Etapa 4 Absoluta'!$E$3:$G$98,3,FALSE),0) -> 215 | H9: =IFERROR(VLOOKUP($C9,'Etapa 5 Absoluta'!$E$3:$G$98,3,FALSE),0) -> 230 | I9: 0 | J9: 0 | K9: 0 | L9: 0 | M9: 0 | N9: {=SUM(LARGE(D9:M9,{1;2;3}))} -> 645
B10: =ROW() - ROW($B$6) + 1 -> 5 | C10: Chema🐗🐗 Martínez Guillamon | D10: 190 | E10: =IFERROR(VLOOKUP($C10,'Etapa 2 Masculina'!$E$3:$G$100,3,FALSE),0) -> 0 | F10: =IFERROR(VLOOKUP($C10,'Etapa 3 Absoluta'!$E$3:$G$98,3,FALSE),0) -> 230 | G10: =IFERROR(VLOOKUP($C10,'Etapa 4 Absoluta'!$E$3:$G$98,3,FALSE),0) -> 190 | H10: =IFERROR(VLOOKUP($C10,'Etapa 5 Absoluta'!$E$3:$G$98,3,FALSE),0) -> 185 | I10: 0 | J10: 0 | K10: 0 | L10: 0 | M10: 0 | N10: {=SUM(LARGE(D10:M10,{1;2;3}))} -> 610
B11: =ROW() - ROW($B$6) + 1 -> 6 | C11: Eduardo Martin Rodriguez | D11: 120 | E11: =IFERROR(VLOOKUP($C11,'Etapa 2 Masculina'!$E$3:$G$100,3,FALSE),0) -> 200 | F11: =IFERROR(VLOOKUP($C11,'Etapa 3 Absoluta'!$E$3:$G$98,3,FALSE),0) -> 185 | G11: =IFERROR(VLOOKUP($C11,'Etapa 4 Absoluta'!$E$3:$G$98,3,FALSE),0) -> 200 | H11: =IFERROR(VLOOKUP($C11,'Etapa 5 Absoluta'!$E$3:$G$98,3,FALSE),0) -> 130 | I11: 0 | J11: 0 | K11: 0 | L11: 0 | M11: 0 | N11: {=SUM(LARGE(D11:M11,{1;2;3}))} -> 585
B12: =ROW() - ROW($B$6) + 1 -> 7 | C12: Alberto Leiva cañada | D12: 95 | E12: =IFERROR(VLOOKUP($C12,'Etapa 2 Masculina'!$E$3:$G$100,3,FALSE),0) -> 120 | F12: =IFERROR(VLOOKUP($C12,'Etapa 3 Absoluta'!$E$3:$G$98,3,FALSE),0) -> 170 | G12: =IFERROR(VLOOKUP($C12,'Etapa 4 Absoluta'!$E$3:$G$98,3,FALSE),0) -> 170 | H12: =IFERROR(VLOOKUP($C12,'Etapa 5 Absoluta'!$E$3:$G$98,3,FALSE),0) -> 185 | I12: 0 | J12: 0 | K12: 0 | L12: 0 | M12: 0 | N12: {=SUM(LARGE(D12:M12,{1;2;3}))} -> 525
B13: =ROW() - ROW($B$6) + 1 -> 8 | C13: Jesús Pizarro Gonzálvez | D13: 135 | E13: =IFERROR(VLOOKUP($C13,'Etapa 2 Masculina'!$E$3:$G$100,3,FALSE),0) -> 0 | F13: =IFERROR(VLOOKUP($C13,'Etapa 3 Absoluta'!$E$3:$G$98,3,FALSE),0) -> 110 | G13: =IFERROR(VLOOKUP($C13,'Etapa 4 Absoluta'!$E$3:$G$98,3,FALSE),0) -> 120 | H13: =IFERROR(VLOOKUP($C13,'Etapa 5 Absoluta'!$E$3:$G$98,3,FALSE),0) -> 160 | I13: 0 | J13: 0 | K13: 0 | L13: 0 | M13: 0 | N13: {=SUM(LARGE(D13:M13,{1;2;3}))} -> 415
B14: =ROW() - ROW($B$6) + 1 -> 9 | C14: benito reyes gonzalez | D14: 170 | E14: =IFERROR(VLOOKUP($C14,'Etapa 2 Masculina'!$E$3:$G$100,3,FALSE),0) -> 0 | F14: =IFERROR(VLOOKUP($C14,'Etapa 3 Absoluta'!$E$3:$G$98,3,FALSE),0) -> 185 | G14: =IFERROR(VLOOKUP($C14,'Etapa 4 Absoluta'!$E$3:$G$98,3,FALSE),0) -> 105 | H14: =IFERROR(VLOOKUP($C14,'Etapa 5 Absoluta'!$E$3:$G$98,3,FALSE),0) -> 160 | I14: 0 | J14: 0 | K14: 0 | L14: 0 | M14: 0 | N14: {=SUM(LARGE(D14:M14,{1;2;3}))} -> 515
B15: =ROW() - ROW($B$6) + 1 -> 10 | C15: Alex Trallero Domec | D15: 180 | E15: =IFERROR(VLOOKUP($C15,'Etapa 2 Masculina'!$E$3:$G$100,3,FALSE),0) -> 0 | F15: =IFERROR(VLOOKUP($C15,'Etapa 3 Absoluta'!$E$3:$G$98,3,FALSE),0) -> 150 | G15: =IFERROR(VLOOKUP($C15,'Etapa 4 Absoluta'!$E$3:$G$98,3,FALSE),0) -> 105 | H15: =IFERROR(VLOOKUP($C15,'Etapa 5 Absoluta'!$E$3:$G$98,3,FALSE),0) -> 0 | I15: 0 | J15: 0 | K15: 0 | L15: 0 | M15: 0 | N15: {=SUM(LARGE(D15:M15,{1;2;3}))} -> 435
B16: =ROW() - ROW($B$6) + 1 -> 11 | C16: Xavi Leiva Cañada | D16: 0 | E16: =IFERROR(VLOOKUP($C16,'Etapa 2 Masculina'!$E$3:$G$100,3,FALSE),0) -> 190 | F16: =IFERROR(VLOOKUP($C16,'Etapa 3 Absoluta'!$E$3:$G$98,3,FALSE),0) -> 160 | G16: =IFERROR(VLOOKUP($C16,'Etapa 4 Absoluta'!$E$3:$G$98,3,FALSE),0) -> 140 | H16: =IFERROR(VLOOKUP($C16,'Etapa 5 Absoluta'!$E$3:$G$98,3,FALSE),0) -> 110 | I16: 0 | J16: 0 | K16: 0 | L16: 0 | M16: 0 | N16: {=SUM(LARGE(D16:M16,{1;2;3}))} -> 490
B17: =ROW() - ROW($B$6) + 1 -> 12 | C17: David Linares Ramos | D17: =310/2 -> 155 | E17: =IFERROR(VLOOKUP($C17,'Etapa 2 Masculina'!$E$3:$G$100,3,FALSE),0) -> 110 | F17: =IFERROR(VLOOKUP($C17,'Etapa 3 Absoluta'!$E$3:$G$98,3,FALSE),0) -> 0 | G17: =IFERROR(VLOOKUP($C17,'Etapa 4 Absoluta'!$E$3:$G$98,3,FALSE),0) -> 150 | H17: =IFERROR(VLOOKUP($C17,'Etapa 5 Absoluta'!$E$3:$G$98,3,FALSE),0) -> 130 | I17: 0 | J17: 0 | K17: 0 | L17: 0 | M17: 0 | N17: {=SUM(LARGE(D17:M17,{1;2;3}))} -> 435
B18: =ROW() - ROW($B$6) + 1 -> 13 | C18: Nicola Perra | D18: 200 | E18: =IFERROR(VLOOKUP($C18,'Etapa 2 Masculina'!$E$3:$G$100,3,FALSE),0) -> 0 | F18: =IFERROR(VLOOKUP($C18,'Etapa 3 Absoluta'!$E$3:$G$98,3,FALSE),0) -> 0 | G18: =IFERROR(VLOOKUP($C18,'Etapa 4 Absoluta'!$E$3:$G$98,3,FALSE),0) -> 0 | H18: =IFERROR(VLOOKUP($C18,'Etapa 5 Absoluta'!$E$3:$G$98,3,FALSE),0) -> 0 | I18: 0 | J18: 0 | K18: 0 | L18: 0 | M18: 0 | N18: {=SUM(LARGE(D18:M18,{1;2;3}))} -> 200
B19: =ROW() - ROW($B$6) + 1 -> 14 | C19: David Tellez Viana | D19: 0 | E19: =IFERROR(VLOOKUP($C19,'Etapa 2 Masculina'!$E$3:$G$100,3,FALSE),0) -> 80 | F19: =IFERROR(VLOOKUP($C19,'Etapa 3 Absoluta'!$E$3:$G$98,3,FALSE),0) -> 135 | G19: =IFERROR(VLOOKUP($C19,'Etapa 4 Absoluta'!$E$3:$G$98,3,FALSE),0) -> 87.5 | H19: =IFERROR(VLOOKUP($C19,'Etapa 5 Absoluta'!$E$3:$G$98,3,FALSE),0) -> 160 | I19: 0 | J19: 0 | K19: 0 | L19: 0 | M19: 0 | N19: {=SUM(LARGE(D19:M19,{1;2;3}))} -> 382.5
B20: =ROW() - ROW($B$6) + 1 -> 15 | C20: Raúl Linares Ramos | D20: 62 | E20: =IFERROR(VLOOKUP($C20,'Etapa 2 Masculina'!$E$3:$G$100,3,FALSE),0) -> 140 | F20: =IFERROR(VLOOKUP($C20,'Etapa 3 Absoluta'!$E$3:$G$98,3,FALSE),0) -> 135 | G20: =IFERROR(VLOOKUP($C20,'Etapa 4 Absoluta'!$E$3:$G$98,3,FALSE),0) -> 87.5 | H20: =IFERROR(VLOOKUP($C20,'Etapa 5 Absoluta'!$E$3:$G$98,3,FALSE),0) -> 130 | I20: 0 | J20: 0 | K20: 0 | L20: 0 | M20: 0 | N20: {=SUM(LARGE(D20:M20,{1;2;3}))} -> 405
B21: =ROW() - ROW($B$6) + 1 -> 16 | C21: Sergi Nerin Velasco | D21: 135 | E21: =IFERROR(VLOOKUP($C21,'Etapa 2 Masculina'!$E$3:$G$100,3,FALSE),0) -> 0 | F21: =IFERROR(VLOOKUP($C21,'Etapa 3 Absoluta'!$E$3:$G$98,3,FALSE),0) -> 120 | G21: =IFERROR(VLOOKUP($C21,'Etapa 4 Absoluta'!$E$3:$G$98,3,FALSE),0) -> 0 | H21: =IFERROR(VLOOKUP($C21,'Etapa 5 Absoluta'!$E$3:$G$98,3,FALSE),0) -> 0 | I21: 0 | J21: 0 | K21: 0 | L21: 0 | M21: 0 | N21: {=SUM(LARGE(D21:M21,{1;2;3}))} -> 255
B22: =ROW() - ROW($B$6) + 1 -> 17 | C22: Sergi Pahisa | D22: =IFERROR(VLOOKUP($C22,'Etapa 2 Masculina'!$E$3:$G$100,3,FALSE),0) -> 230 | E22: =IFERROR(VLOOKUP($C22,'Etapa 2 Masculina'!$E$3:$G$100,3,FALSE),0) -> 230 | F22: =IFERROR(VLOOKUP($C22,'Etapa 3 Absoluta'!$E$3:$G$98,3,FALSE),0) -> 0 | G22: =IFERROR(VLOOKUP($C22,'Etapa 4 Absoluta'!$E$3:$G$98,3,FALSE),0) -> 170 | H22: =IFERROR(VLOOKUP($C22,'Etapa 5 Absoluta'!$E$3:$G$98,3,FALSE),0) -> 92.5 | I22: 0 | J22: 0 | K22: 0 | L22: 0 | M22: 0 | N22: {=SUM(LARGE(D22:M22,{1;2;3}))} -> 630
B23: =ROW() - ROW($B$6) + 1 -> 18 | C23: Fernando Martínez Guillamón | D23: 75 | E23: =IFERROR(VLOOKUP($C23,'Etapa 2 Masculina'!$E$3:$G$100,3,FALSE),0) -> 100 | F23: =IFERROR(VLOOKUP($C23,'Etapa 3 Absoluta'!$E$3:$G$98,3,FALSE),0) -> 0 | G23: =IFERROR(VLOOKUP($C23,'Etapa 4 Absoluta'!$E$3:$G$98,3,FALSE),0) -> 95 | H23: =IFERROR(VLOOKUP($C23,'Etapa 5 Absoluta'!$E$3:$G$98,3,FALSE),0) -> 0 | I23: 0 | J23: 0 | K23: 0 | L23: 0 | M23: 0 | N23: {=SUM(LARGE(D23:M23,{1;2;3}))} -> 270
B24: =ROW() - ROW($B$6) + 1 -> 19 | C24: ivan luengo robles | E24: =IFERROR(VLOOKUP($C24,'Etapa 2 Masculina'!$E$3:$G$100,3,FALSE),0) -> 150 | F24: =IFERROR(VLOOKUP($C24,'Etapa 3 Absoluta'!$E$3:$G$98,3,FALSE),0) -> 0 | G24: =IFERROR(VLOOKUP($C24,'Etapa 4 Absoluta'!$E$3:$G$98,3,FALSE),0) -> 130 | H24: =IFERROR(VLOOKUP($C24,'Etapa 5 Absoluta'!$E$3:$G$98,3,FALSE),0) -> 92.5 | I24: 0 | J24: 0 | K24: 0 | L24: 0 | M24: 0 | N24: {=SUM(LARGE(D24:M24,{1;2;3}))} -> 372.5
B25: =ROW() - ROW($B$6) + 1 -> 20 | C25: Pau Blas Molina | D25: =310/2 -> 155 | E25: =IFERROR(VLOOKUP($C25,'Etapa 2 Masculina'!$E$3:$G$100,3,FALSE),0) -> 0 | F25: =IFERROR(VLOOKUP($C25,'Etapa 3 Absoluta'!$E$3:$G$98,3,FALSE),0) -> 0 | G25: =IFERROR(VLOOKUP($C25,'Etapa 4 Absoluta'!$E$3:$G$98,3,FALSE),0) -> 0 | H25: =IFERROR(VLOOKUP($C25,'Etapa 5 Absoluta'!$E$3:$G$98,3,FALSE),0) -> 0 | I25: 0 | J25: 0 | K25: 0 | L25: 0 | M25: 0 | N25: {=SUM(LARGE(D25:M25,{1;2;3}))} -> 155
B26: =ROW() - ROW($B$6) + 1 -> 21 | C26: Sergi Perez Vilar | D26: 0 | E26: =IFERROR(VLOOKUP($C26,'Etapa 2 Masculina'!$E$3:$G$100,3,FALSE),0) -> 0 | F26: =IFERROR(VLOOKUP($C26,'Etapa 3 Absoluta'!$E$3:$G$98,3,FALSE),0) -> 0 | G26: =IFERROR(VLOOKUP($C26,'Etapa 4 Absoluta'!$E$3:$G$98,3,FALSE),0) -> 0 | H26: =IFERROR(VLOOKUP($C26,'Etapa 5 Absoluta'!$E$3:$G$98,3,FALSE),0) -> 0 | I26: 0 | J26: 0 | K26: 0 | L26: 0 | M26: 0 | N26: {=SUM(LARGE(D26:M26,{1;2;3}))} -> 0
B27: =ROW() - ROW($B$6) + 1 -> 22 | C27: Giacomo Bonacini | D27: 58 | E27: =IFERROR(VLOOKUP($C27,'Etapa 2 Masculina'!$E$3:$G$100,3,FALSE),0) -> 70 | F27: =IFERROR(VLOOKUP($C27,'Etapa 3 Absoluta'!$E$3:$G$98,3,FALSE),0) -> 0 | G27: =IFERROR(VLOOKUP($C27,'Etapa 4 Absoluta'!$E$3:$G$98,3,FALSE),0) -> 70.333333 | H27: =IFERROR(VLOOKUP($C27,'Etapa 5 Absoluta'!$E$3:$G$98,3,FALSE),0) -> 0 | I27: 0 | J27: 0 | K27: 0 | L27: 0 | M27: 0 | N27: {=SUM(LARGE(D27:M27,{1;2;3}))} -> 198.33333
B28: =ROW() - ROW($B$6) + 1 -> 23 | C28: Mario Morón Sancho | D28: =IFERROR(VLOOKUP($C28,'Etapa 2 Masculina'!$E$3:$G$100,3,FALSE),0) -> 130 | E28: =IFERROR(VLOOKUP($C28,'Etapa 2 Masculina'!$E$3:$G$100,3,FALSE),0) -> 130 | F28: =IFERROR(VLOOKUP($C28,'Etapa 3 Absoluta'!$E$3:$G$98,3,FALSE),0) -> 0 | G28: =IFERROR(VLOOKUP($C28,'Etapa 4 Absoluta'!$E$3:$G$98,3,FALSE),0) -> 70.333333 | H28: =IFERROR(VLOOKUP($C28,'Etapa 5 Absoluta'!$E$3:$G$98,3,FALSE),0) -> 92.5 | I28: 0 | J28: 0 | K28: 0 | L28: 0 | M28: 0 | N28: {=SUM(LARGE(D28:M28,{1;2;3}))} -> 352.5
B29: =ROW() - ROW($B$6) + 1 -> 24 | C29: Marc Arrebola Sans | D29: 66 | E29: =IFERROR(VLOOKUP($C29,'Etapa 2 Masculina'!$E$3:$G$100,3,FALSE),0) -> 0 | F29: =IFERROR(VLOOKUP($C29,'Etapa 3 Absoluta'!$E$3:$G$98,3,FALSE),0) -> 0 | G29: =IFERROR(VLOOKUP($C29,'Etapa 4 Absoluta'!$E$3:$G$98,3,FALSE),0) -> 0 | H29: =IFERROR(VLOOKUP($C29,'Etapa 5 Absoluta'!$E$3:$G$98,3,FALSE),0) -> 92.5 | I29: 0 | J29: 0 | K29: 0 | L29: 0 | M29: 0 | N29: {=SUM(LARGE(D29:M29,{1;2;3}))} -> 158.5
B30: =ROW() - ROW($B$6) + 1 -> 25 | C30: Joan Torre Rodríguez | D30: 100 | E30: =IFERROR(VLOOKUP($C30,'Etapa 2 Masculina'!$E$3:$G$100,3,FALSE),0) -> 0 | F30: =IFERROR(VLOOKUP($C30,'Etapa 3 Absoluta'!$E$3:$G$98,3,FALSE),0) -> 0 | G30: =IFERROR(VLOOKUP($C30,'Etapa 4 Absoluta'!$E$3:$G$98,3,FALSE),0) -> 0 | H30: =IFERROR(VLOOKUP($C30,'Etapa 5 Absoluta'!$E$3:$G$98,3,FALSE),0) -> 0 | I30: 0 | J30: 0 | K30: 0 | L30: 0 | M30: 0 | N30: {=SUM(LARGE(D30:M30,{1;2;3}))} -> 100
B31: =ROW() - ROW($B$6) + 1 -> 26 | C31: Guillem Moya Niubó | D31: 0 | E31: =IFERROR(VLOOKUP($C31,'Etapa 2 Masculina'!$E$3:$G$100,3,FALSE),0) -> 0 | F31: =IFERROR(VLOOKUP($C31,'Etapa 3 Absoluta'!$E$3:$G$98,3,FALSE),0) -> 0 | G31: =IFERROR(VLOOKUP($C31,'Etapa 4 Absoluta'!$E$3:$G$98,3,FALSE),0) -> 62 | H31: =IFERROR(VLOOKUP($C31,'Etapa 5 Absoluta'!$E$3:$G$98,3,FALSE),0) -> 0 | I31: 0 | J31: 0 | K31: 0 | L31: 0 | M31: 0 | N31: {=SUM(LARGE(D31:M31,{1;2;3}))} -> 62
B32: =ROW() - ROW($B$6) + 1 -> 27 | C32: Marc Company Salvat | D32: =IFERROR(VLOOKUP($C32,'Etapa 2 Masculina'!$E$3:$G$100,3,FALSE),0) -> 92.5 | E32: =IFERROR(VLOOKUP($C32,'Etapa 2 Masculina'!$E$3:$G$100,3,FALSE),0) -> 92.5 | F32: =IFERROR(VLOOKUP($C32,'Etapa 3 Absoluta'!$E$3:$G$98,3,FALSE),0) -> 0 | G32: =IFERROR(VLOOKUP($C32,'Etapa 4 Absoluta'!$E$3:$G$98,3,FALSE),0) -> 70.333333 | H32: =IFERROR(VLOOKUP($C32,'Etapa 5 Absoluta'!$E$3:$G$98,3,FALSE),0) -> 80 | I32: 0 | J32: 0 | K32: 0 | L32: 0 | M32: 0 | N32: {=SUM(LARGE(D32:M32,{1;2;3}))} -> 265
B33: =ROW() - ROW($B$6) + 1 -> 28 | C33: David Gallego | D33: 80 | E33: =IFERROR(VLOOKUP($C33,'Etapa 2 Masculina'!$E$3:$G$100,3,FALSE),0) -> 0 | F33: =IFERROR(VLOOKUP($C33,'Etapa 3 Absoluta'!$E$3:$G$98,3,FALSE),0) -> 0 | G33: =IFERROR(VLOOKUP($C33,'Etapa 4 Absoluta'!$E$3:$G$98,3,FALSE),0) -> 0 | H33: =IFERROR(VLOOKUP($C33,'Etapa 5 Absoluta'!$E$3:$G$98,3,FALSE),0) -> 0 | I33: 0 | J33: 0 | K33: 0 | L33: 0 | M33: 0 | N33: {=SUM(LARGE(D33:M33,{1;2;3}))} -> 80
B34: =ROW() - ROW($B$6) + 1 -> 29 | C34: Xavier Altimira Gómez | D34: 0 | E34: =IFERROR(VLOOKUP($C34,'Etapa 2 Masculina'!$E$3:$G$100,3,FALSE),0) -> 0 | F34: =IFERROR(VLOOKUP($C34,'Etapa 3 Absoluta'!$E$3:$G$98,3,FALSE),0) -> 0 | G34: =IFERROR(VLOOKUP($C34,'Etapa 4 Absoluta'!$E$3:$G$98,3,FALSE),0) -> 0 | H34: =IFERROR(VLOOKUP($C34,'Etapa 5 Absoluta'!$E$3:$G$98,3,FALSE),0) -> 0 | I34: 0 | J34: 0 | K34: 0 | L34: 0 | M34: 0 | N34: {=SUM(LARGE(D34:M34,{1;2;3}))} -> 0
B35: =ROW() - ROW($B$6) + 1 -> 30 | C35: Albert Arrebola Sans | D35: 90 | E35: =IFERROR(VLOOKUP($C35,'Etapa 2 Masculina'!$E$3:$G$100,3,FALSE),0) -> 0 | F35: =IFERROR(VLOOKUP($C35,'Etapa 3 Absoluta'!$E$3:$G$98,3,FALSE),0) -> 0 | G35: =IFERROR(VLOOKUP($C35,'Etapa 4 Absoluta'!$E$3:$G$98,3,FALSE),0) -> 0 | H35: =IFERROR(VLOOKUP($C35,'Etapa 5 Absoluta'!$E$3:$G$98,3,FALSE),0) -> 0 | I35: 0 | J35: 0 | K35: 0 | L35: 0 | M35: 0 | N35: {=SUM(LARGE(D35:M35,{1;2;3}))} -> 90
B36: =ROW() - ROW($B$6) + 1 -> 31 | C36: adria alonso marti | D36: 85 | E36: =IFERROR(VLOOKUP($C36,'Etapa 2 Masculina'!$E$3:$G$100,3,FALSE),0) -> 0 | F36: =IFERROR(VLOOKUP($C36,'Etapa 3 Absoluta'!$E$3:$G$98,3,FALSE),0) -> 0 | G36: =IFERROR(VLOOKUP($C36,'Etapa 4 Absoluta'!$E$3:$G$98,3,FALSE),0) -> 0 | H36: =IFERROR(VLOOKUP($C36,'Etapa 5 Absoluta'!$E$3:$G$98,3,FALSE),0) -> 0 | I36: 0 | J36: 0 | K36: 0 | L36: 0 | M36: 0 | N36: {=SUM(LARGE(D36:M36,{1;2;3}))} -> 85
B37: =ROW() - ROW($B$6) + 1 -> 32 | C37: cristian debon viñas | D37: 0 | E37: =IFERROR(VLOOKUP($C37,'Etapa 2 Masculina'!$E$3:$G$100,3,FALSE),0) -> 0 | F37: =IFERROR(VLOOKUP($C37,'Etapa 3 Absoluta'!$E$3:$G$98,3,FALSE),0) -> 0 | G37: =IFERROR(VLOOKUP($C37,'Etapa 4 Absoluta'!$E$3:$G$98,3,FALSE),0) -> 0 | H37: =IFERROR(VLOOKUP($C37,'Etapa 5 Absoluta'!$E$3:$G$98,3,FALSE),0) -> 0 | I37: 0 | J37: 0 | K37: 0 | L37: 0 | M37: 0 | N37: {=SUM(LARGE(D37:M37,{1;2;3}))} -> 0
B38: =ROW() - ROW($B$6) + 1 -> 33 | C38: guillermo Beroy Álvarez | D38: 70 | E38: =IFERROR(VLOOKUP($C38,'Etapa 2 Masculina'!$E$3:$G$100,3,FALSE),0) -> 0 | F38: =IFERROR(VLOOKUP($C38,'Etapa 3 Absoluta'!$E$3:$G$98,3,FALSE),0) -> 0 | G38: =IFERROR(VLOOKUP($C38,'Etapa 4 Absoluta'!$E$3:$G$98,3,FALSE),0) -> 0 | H38: =IFERROR(VLOOKUP($C38,'Etapa 5 Absoluta'!$E$3:$G$98,3,FALSE),0) -> 0 | I38: 0 | J38: 0 | K38: 0 | L38: 0 | M38: 0 | N38: {=SUM(LARGE(D38:M38,{1;2;3}))} -> 70
B39: =ROW() - ROW($B$6) + 1 -> 34 | C39: Leandro Ezequiel Casas Di Lorenzo | D39: 0 | E39: =IFERROR(VLOOKUP($C39,'Etapa 2 Masculina'!$E$3:$G$100,3,FALSE),0) -> 0 | F39: =IFERROR(VLOOKUP($C39,'Etapa 3 Absoluta'!$E$3:$G$98,3,FALSE),0) -> 0 | G39: =IFERROR(VLOOKUP($C39,'Etapa 4 Absoluta'!$E$3:$G$98,3,FALSE),0) -> 80 | H39: =IFERROR(VLOOKUP($C39,'Etapa 5 Absoluta'!$E$3:$G$98,3,FALSE),0) -> 0 | I39: 0 | J39: 0 | K39: 0 | L39: 0 | M39: 0 | N39: {=SUM(LARGE(D39:M39,{1;2;3}))} -> 80
B40: =ROW() - ROW($B$6) + 1 -> 35 | C40: Aleix Martínez Muñoz | D40: 0 | E40: =IFERROR(VLOOKUP($C40,'Etapa 2 Masculina'!$E$3:$G$100,3,FALSE),0) -> 0 | F40: =IFERROR(VLOOKUP($C40,'Etapa 3 Absoluta'!$E$3:$G$98,3,FALSE),0) -> 0 | G40: =IFERROR(VLOOKUP($C40,'Etapa 4 Absoluta'!$E$3:$G$98,3,FALSE),0) -> 58 | H40: =IFERROR(VLOOKUP($C40,'Etapa 5 Absoluta'!$E$3:$G$98,3,FALSE),0) -> 0 | I40: 0 | J40: 0 | K40: 0 | L40: 0 | M40: 0 | N40: {=SUM(LARGE(D40:M40,{1;2;3}))} -> 58
B41: =ROW() - ROW($B$6) + 1 -> 36 | C41: Aitor Martin Maldonado | E41: =IFERROR(VLOOKUP($C41,'Etapa 2 Masculina'!$E$3:$G$100,3,FALSE),0) -> 0 | F41: =IFERROR(VLOOKUP($C41,'Etapa 3 Absoluta'!$E$3:$G$98,3,FALSE),0) -> 0 | G41: =IFERROR(VLOOKUP($C41,'Etapa 4 Absoluta'!$E$3:$G$98,3,FALSE),0) -> 0 | H41: =IFERROR(VLOOKUP($C41,'Etapa 5 Absoluta'!$E$3:$G$98,3,FALSE),0) -> 0 | N41: {=SUM(LARGE(D41:M41,{1;2;3}))} -> 0
B42: =ROW() - ROW($B$6) + 1 -> 37 | C42: David Cortés Segura | E42: =IFERROR(VLOOKUP($C42,'Etapa 2 Masculina'!$E$3:$G$100,3,FALSE),0) -> 0 | F42: =IFERROR(VLOOKUP($C42,'Etapa 3 Absoluta'!$E$3:$G$98,3,FALSE),0) -> 0 | G42: =IFERROR(VLOOKUP($C42,'Etapa 4 Absoluta'!$E$3:$G$98,3,FALSE),0) -> 0 | H42: =IFERROR(VLOOKUP($C42,'Etapa 5 Absoluta'!$E$3:$G$98,3,FALSE),0) -> 0 | N42: {=SUM(LARGE(D42:M42,{1;2;3}))} -> 0
B43: =ROW() - ROW($B$6) + 1 -> 38 | C43: David Rojo Dengra | E43: =IFERROR(VLOOKUP($C43,'Etapa 2 Masculina'!$E$3:$G$100,3,FALSE),0) -> 0 | F43: =IFERROR(VLOOKUP($C43,'Etapa 3 Absoluta'!$E$3:$G$98,3,FALSE),0) -> 0 | G43: =IFERROR(VLOOKUP($C43,'Etapa 4 Absoluta'!$E$3:$G$98,3,FALSE),0) -> 0 | H43: =IFERROR(VLOOKUP($C43,'Etapa 5 Absoluta'!$E$3:$G$98,3,FALSE),0) -> 0 | N43: {=SUM(LARGE(D43:M43,{1;2;3}))} -> 0
...

Sheet Ranking Masculino
B3: RANKING MASCULINO
B5: Posicion | C5: FOOTGOLFER NICKNAME | D5: Etapa 1 | E5: Etapa 2 | F5: Etapa 3 | G5: Etapa 4 | H5: Etapa 5 | I5: Etapa 6 | J5: Etapa 7 | K5: Etapa 8 | L5: Etapa 9 | M5: Etapa 10 | N5: Etapa 11 | O5: Etapa 12 | P5: Total | Q5: Maxima puntuacion posible
B6: 1 | C6: Jorge Santiago Buqueras | D6: =IFERROR(VLOOKUP($C6,'Etapa 1 Masculino'!$E$3:$G$99,3,FALSE),0) -> 250 | E6: =IFERROR(VLOOKUP($C6,'Etapa 2 Masculina'!$E$3:$G$99,3,FALSE),0) -> 250 | F6: 0 | G6: 0 | H6: 0 | I6: 0 | J6: 0 | K6: 0 | L6: 0 | M6: 0 | N6: 0 | O6: 0 | P6: {=SUM(LARGE(D6:O6,{1;2;3;4;5;6;7;8}))} -> 500 | Q6: {=SUM(LARGE(CHOOSE({1,2,3,4,5,6,7,8,9,10}, D6, E6, F6, G6, H6, I6, J6, K6, L6, 250), {1,2,3,4,5,6,7}))} -> 750 | U6: Primero | V6: jorge
B7: =ROW() - ROW($B$6) + 1 -> 2 | C7: Sergi Pahisa | D7: =IFERROR(VLOOKUP($C7,'Etapa 1 Masculino'!$E$3:$G$99,3,FALSE),0) -> 200 | E7: =IFERROR(VLOOKUP($C7,'Etapa 2 Masculina'!$E$3:$G$99,3,FALSE),0) -> 230 | F7: 0 | G7: 0 | H7: 0 | I7: 0 | J7: 0 | K7: 0 | L7: 0 | M7: 0 | N7: 0 | O7: 0 | P7: {=SUM(LARGE(D7:O7,{1;2;3;4;5;6;7;8}))} -> 430 | Q7: {=SUM(LARGE(CHOOSE({1,2,3,4,5,6,7,8,9,10}, D7, E7, F7, G7, H7, I7, J7, K7, L7, 250), {1,2,3,4,5,6,7}))} -> 680 | U7: Segundo | V7: Chema
B8: =ROW() - ROW($B$6) + 1 -> 3 | C8: Xavi Leiva Cañada | D8: =IFERROR(VLOOKUP($C8,'Etapa 1 Masculino'!$E$3:$G$99,3,FALSE),0) -> 230 | E8: =IFERROR(VLOOKUP($C8,'Etapa 2 Masculina'!$E$3:$G$99,3,FALSE),0) -> 190 | F8: 0 | G8: 0 | H8: 0 | I8: 0 | J8: 0 | K8: 0 | L8: 0 | M8: 0 | N8: 0 | O8: 0 | P8: {=SUM(LARGE(D8:O8,{1;2;3;4;5;6;7;8}))} -> 420 | Q8: {=SUM(LARGE(CHOOSE({1,2,3,4,5,6,7,8,9,10}, D8, E8, F8, G8, H8, I8, J8, K8, L8, 250), {1,2,3,4,5,6,7}))} -> 670 | U8: Tercero | V8: JuanRa
B9: =ROW() - ROW($B$6) + 1 -> 4 | C9: Olivier TRESSENS | D9: =IFERROR(VLOOKUP($C9,'Etapa 1 Masculino'!$E$3:$G$99,3,FALSE),0) -> 190 | E9: =IFERROR(VLOOKUP($C9,'Etapa 2 Masculina'!$E$3:$G$99,3,FALSE),0) -> 215 | F9: 0 | G9: 0 | H9: 0 | I9: 0 | J9: 0 | K9: 0 | L9: 0 | M9: 0 | N9: 0 | O9: 0 | P9: {=SUM(LARGE(D9:O9,{1;2;3;4;5;6;7;8}))} -> 405 | Q9: {=SUM(LARGE(CHOOSE({1,2,3,4,5,6,7,8,9,10}, D9, E9, F9, G9, H9, I9, J9, K9, L9, 250), {1,2,3,4,5,6,7}))} -> 655
B10: =ROW() - ROW($B$6) + 1 -> 5 | C10: Chema Martínez Guillamon | D10: =IFERROR(VLOOKUP($C10,'Etapa 1 Masculino'!$E$3:$G$99,3,FALSE),0) -> 215 | E10: =IFERROR(VLOOKUP($C10,'Etapa 2 Masculina'!$E$3:$G$99,3,FALSE),0) -> 165 | F10: 0 | G10: 0 | H10: 0 | I10: 0 | J10: 0 | K10: 0 | L10: 0 | M10: 0 | N10: 0 | O10: 0 | P10: {=SUM(LARGE(D10:O10,{1;2;3;4;5;6;7;8}))} -> 380 | Q10: {=SUM(LARGE(CHOOSE({1,2,3,4,5,6,7,8,9,10}, D10, E10, F10, G10, H10, I10, J10, K10, L10, 250), {1,2,3,4,5,6,7}))} -> 630
B11: =ROW() - ROW($B$6) + 1 -> 6 | C11: JuanRa Perez | D11: =IFERROR(VLOOKUP($C11,'Etapa 1 Masculino'!$E$3:$G$99,3,FALSE),0) -> 180 | E11: =IFERROR(VLOOKUP($C11,'Etapa 2 Masculina'!$E$3:$G$99,3,FALSE),0) -> 180 | F11: 0 | G11: 0 | H11: 0 | I11: 0 | J11: 0 | K11: 0 | L11: 0 | M11: 0 | N11: 0 | O11: 0 | P11: {=SUM(LARGE(D11:O11,{1;2;3;4;5;6;7;8}))} -> 360 | Q11: {=SUM(LARGE(CHOOSE({1,2,3,4,5,6,7,8,9,10}, D11, E11, F11, G11, H11, I11, J11, K11, L11, 250), {1,2,3,4,5,6,7}))} -> 610
B12: =ROW() - ROW($B$6) + 1 -> 7 | C12: Alberto Leiva cañada | D12: =IFERROR(VLOOKUP($C12,'Etapa 1 Masculino'!$E$3:$G$99,3,FALSE),0) -> 170 | E12: =IFERROR(VLOOKUP($C12,'Etapa 2 Masculina'!$E$3:$G$99,3,FALSE),0) -> 120 | F12: 0 | G12: 0 | H12: 0 | I12: 0 | J12: 0 | K12: 0 | L12: 0 | M12: 0 | N12: 0 | O12: 0 | P12: {=SUM(LARGE(D12:O12,{1;2;3;4;5;6;7;8}))} -> 290 | Q12: {=SUM(LARGE(CHOOSE({1,2,3,4,5,6,7,8,9,10}, D12, E12, F12, G12, H12, I12, J12, K12, L12, 250), {1,2,3,4,5,6,7}))} -> 540
B13: =ROW() - ROW($B$6) + 1 -> 8 | C13: Mario Morón Sancho | D13: =IFERROR(VLOOKUP($C13,'Etapa 1 Masculino'!$E$3:$G$99,3,FALSE),0) -> 125 | E13: =IFERROR(VLOOKUP($C13,'Etapa 2 Masculina'!$E$3:$G$99,3,FALSE),0) -> 130 | F13: 0 | G13: 0 | H13: 0 | I13: 0 | J13: 0 | K13: 0 | L13: 0 | M13: 0 | N13: 0 | O13: 0 | P13: {=SUM(LARGE(D13:O13,{1;2;3;4;5;6;7;8}))} -> 255 | Q13: {=SUM(LARGE(CHOOSE({1,2,3,4,5,6,7,8,9,10}, D13, E13, F13, G13, H13, I13, J13, K13, L13, 250), {1,2,3,4,5,6,7}))} -> 505
B14: =ROW() - ROW($B$6) + 1 -> 9 | C14: ivan luengo robles | D14: =IFERROR(VLOOKUP($C14,'Etapa 1 Masculino'!$E$3:$G$99,3,FALSE),0) -> 105 | E14: =IFERROR(VLOOKUP($C14,'Etapa 2 Masculina'!$E$3:$G$99,3,FALSE),0) -> 150 | F14: 0 | G14: 0 | H14: 0 | I14: 0 | J14: 0 | K14: 0 | L14: 0 | M14: 0 | N14: 0 | O14: 0 | P14: {=SUM(LARGE(D14:O14,{1;2;3;4;5;6;7;8}))} -> 255 | Q14: {=SUM(LARGE(CHOOSE({1,2,3,4,5,6,7,8,9,10}, D14, E14, F14, G14, H14, I14, J14, K14, L14, 250), {1,2,3,4,5,6,7}))} -> 505
B15: =ROW() - ROW($B$6) + 1 -> 10 | C15: Daniel Abril Amador | D15: =IFERROR(VLOOKUP($C15,'Etapa 1 Masculino'!$E$3:$G$99,3,FALSE),0) -> 85 | E15: =IFERROR(VLOOKUP($C15,'Etapa 2 Masculina'!$E$3:$G$99,3,FALSE),0) -> 165 | F15: 0 | G15: 0 | H15: 0 | I15: 0 | J15: 0 | K15: 0 | L15: 0 | M15: 0 | N15: 0 | O15: 0 | P15: {=SUM(LARGE(D15:O15,{1;2;3;4;5;6;7;8}))} -> 250 | Q15: {=SUM(LARGE(CHOOSE({1,2,3,4,5,6,7,8,9,10}, D15, E15, F15, G15, H15, I15, J15, K15, L15, 250), {1,2,3,4,5,6,7}))} -> 500
B16: =ROW() - ROW($B$6) + 1 -> 11 | C16: Raúl Linares Ramos | D16: =IFERROR(VLOOKUP($C16,'Etapa 1 Masculino'!$E$3:$G$99,3,FALSE),0) -> 105 | E16: =IFERROR(VLOOKUP($C16,'Etapa 2 Masculina'!$E$3:$G$99,3,FALSE),0) -> 140 | F16: 0 | G16: 0 | H16: 0 | I16: 0 | J16: 0 | K16: 0 | L16: 0 | M16: 0 | N16: 0 | O16: 0 | P16: {=SUM(LARGE(D16:O16,{1;2;3;4;5;6;7;8}))} -> 245 | Q16: {=SUM(LARGE(CHOOSE({1,2,3,4,5,6,7,8,9,10}, D16, E16, F16, G16, H16, I16, J16, K16, L16, 250), {1,2,3,4,5,6,7}))} -> 495
B17: =ROW() - ROW($B$6) + 1 -> 12 | C17: David Tellez Viana | D17: =IFERROR(VLOOKUP($C17,'Etapa 1 Masculino'!$E$3:$G$99,3,FALSE),0) -> 145 | E17: =IFERROR(VLOOKUP($C17,'Etapa 2 Masculina'!$E$3:$G$99,3,FALSE),0) -> 80 | F17: 0 | G17: 0 | H17: 0 | I17: 0 | J17: 0 | K17: 0 | L17: 0 | M17: 0 | N17: 0 | O17: 0 | P17: {=SUM(LARGE(D17:O17,{1;2;3;4;5;6;7;8}))} -> 225 | Q17: {=SUM(LARGE(CHOOSE({1,2,3,4,5,6,7,8,9,10}, D17, E17, F17, G17, H17, I17, J17, K17, L17, 250), {1,2,3,4,5,6,7}))} -> 475
B18: =ROW() - ROW($B$6) + 1 -> 13 | C18: Eduardo Martin Rodriguez | D18: =IFERROR(VLOOKUP($C18,'Etapa 1 Masculino'!$E$3:$G$99,3,FALSE),0) -> 0 | E18: =IFERROR(VLOOKUP($C18,'Etapa 2 Masculina'!$E$3:$G$99,3,FALSE),0) -> 200 | F18: 0 | G18: 0 | H18: 0 | I18: 0 | J18: 0 | K18: 0 | L18: 0 | M18: 0 | N18: 0 | O18: 0 | P18: {=SUM(LARGE(D18:O18,{1;2;3;4;5;6;7;8}))} -> 200 | Q18: {=SUM(LARGE(CHOOSE({1,2,3,4,5,6,7,8,9,10}, D18, E18, F18, G18, H18, I18, J18, K18, L18, 250), {1,2,3,4,5,6,7}))} -> 450
B19: =ROW() - ROW($B$6) + 1 -> 14 | C19: Fernando Martínez Guillamón | D19: =IFERROR(VLOOKUP($C19,'Etapa 1 Masculino'!$E$3:$G$99,3,FALSE),0) -> 90 | E19: =IFERROR(VLOOKUP($C19,'Etapa 2 Masculina'!$E$3:$G$99,3,FALSE),0) -> 100 | F19: 0 | G19: 0 | H19: 0 | I19: 0 | J19: 0 | K19: 0 | L19: 0 | M19: 0 | N19: 0 | O19: 0 | P19: {=SUM(LARGE(D19:O19,{1;2;3;4;5;6;7;8}))} -> 190 | Q19: {=SUM(LARGE(CHOOSE({1,2,3,4,5,6,7,8,9,10}, D19, E19, F19, G19, H19, I19, J19, K19, L19, 250), {1,2,3,4,5,6,7}))} -> 440
B20: =ROW() - ROW($B$6) + 1 -> 15 | C20: Gustavo Verse | D20: =IFERROR(VLOOKUP($C20,'Etapa 1 Masculino'!$E$3:$G$99,3,FALSE),0) -> 95 | E20: =IFERROR(VLOOKUP($C20,'Etapa 2 Masculina'!$E$3:$G$99,3,FALSE),0) -> 85 | F20: 0 | G20: 0 | H20: 0 | I20: 0 | J20: 0 | K20: 0 | L20: 0 | M20: 0 | N20: 0 | O20: 0 | P20: {=SUM(LARGE(D20:O20,{1;2;3;4;5;6;7;8}))} -> 180 | Q20: {=SUM(LARGE(CHOOSE({1,2,3,4,5,6,7,8,9,10}, D20, E20, F20, G20, H20, I20, J20, K20, L20, 250), {1,2,3,4,5,6,7}))} -> 430
... B52: =ROW() - ROW($B$6) + 1 -> 47 | C52: guillermo Beroy Álvarez | D52: =IFERROR(VLOOKUP($C52,'Etapa 1 Masculino'!$E$3:$G$99,3,FALSE),0) -> 0 | E52: =IFERROR(VLOOKUP($C52,'Etapa 2 Masculina'!$E$3:$G$99,3,FALSE),0) -> 0 | F52: 0 | G52: 0 | H52: 0 | I52: 0 | J52: 0 | K52: 0 | L52: 0 | M52: 0 | N52: 0 | O52: 0 | P52: {=SUM(LARGE(D52:O52,{1;2;3;4;5;6;7;8}))} -> 0 | Q52: {=SUM(LARGE(CHOOSE({1,2,3,4,5,6,7,8,9,10}, D52, E52, F52, G52, H52, I52, J52, K52, L52, 250), {1,2,3,4,5,6,7}))} -> 250

Sheet Ranking Senior
B3: RANKING SENIOR
B5: Posicion | C5: FOOTGOLFER NICKNAME | D5: Etapa 1 | E5: Etapa 2 | F5: Etapa 3 | G5: Etapa 4 | H5: Etapa 5 | I5: Etapa 6 | J5: Etapa 7 | K5: Etapa 8 | L5: Etapa 9 | M5: Etapa 10 | N5: Etapa 11 | O5: Etapa 12 | P5: Total | Q5: Maxima puntuacion posible
B6: =ROW() - ROW($B$6) + 1 -> 1 | C6: Olivier TRESSENS | D6: =IFERROR(VLOOKUP($C6,'Etapa 1 Senior'!$E$3:$G$83,3,FALSE),0) -> 250 | E6: =IFERROR(VLOOKUP($C6,'Etapa 2 Senior'!$E$3:$G$83,3,FALSE),0) -> 250 | F6: 0 | G6: 0 | H6: 0 | I6: 0 | J6: 0 | K6: 0 | L6: 0 | M6: 0 | N6: 0 | O6: 0 | P6: {=SUM(LARGE(D6:O6,{1;2;3;4;5;6;7;8}))} -> 500 | Q6: {=SUM(LARGE(CHOOSE({1,2,3,4,5,6,7,8,9,10}, D6, E6, F6, G6, H6, I6, J6, K6, L6, 250), {1,2,3,4,5,6,7}))} -> 750 | U6: Primero | V6: jorge
B7: =ROW() - ROW($B$6) + 1 -> 2 | C7: Raúl Linares Ramos | D7: =IFERROR(VLOOKUP($C7,'Etapa 1 Senior'!$E$3:$G$83,3,FALSE),0) -> 230 | E7: =IFERROR(VLOOKUP($C7,'Etapa 2 Senior'!$E$3:$G$83,3,FALSE),0) -> 230 | F7: 0 | G7: 0 | H7: 0 | I7: 0 | J7: 0 | K7: 0 | L7: 0 | M7: 0 | N7: 0 | O7: 0 | P7: {=SUM(LARGE(D7:O7,{1;2;3;4;5;6;7;8}))} -> 460 | Q7: {=SUM(LARGE(CHOOSE({1,2,3,4,5,6,7,8,9,10}, D7, E7, F7, G7, H7, I7, J7, K7, L7, 250), {1,2,3,4,5,6,7}))} -> 710 | U7: Segundo | V7: Chema
B8: =ROW() - ROW($B$6) + 1 -> 3 | C8: Gustavo Verse | D8: =IFERROR(VLOOKUP($C8,'Etapa 1 Senior'!$E$3:$G$83,3,FALSE),0) -> 215 | E8: =IFERROR(VLOOKUP($C8,'Etapa 2 Senior'!$E$3:$G$83,3,FALSE),0) -> 190 | F8: 0 | G8: 0 | H8: 0 | I8: 0 | J8: 0 | K8: 0 | L8: 0 | M8: 0 | N8: 0 | O8: 0 | P8: {=SUM(LARGE(D8:O8,{1;2;3;4;5;6;7;8}))} -> 405 | Q8: {=SUM(LARGE(CHOOSE({1,2,3,4,5,6,7,8,9,10}, D8, E8, F8, G8, H8, I8, J8, K8, L8, 250), {1,2,3,4,5,6,7}))} -> 655 | U8: Tercero | V8: JuanRa
B9: =ROW() - ROW($B$6) + 1 -> 4 | C9: Fernando Martínez Guillamón | D9: =IFERROR(VLOOKUP($C9,'Etapa 1 Senior'!$E$3:$G$83,3,FALSE),0) -> 200 | E9: =IFERROR(VLOOKUP($C9,'Etapa 2 Senior'!$E$3:$G$83,3,FALSE),0) -> 200 | F9: 0 | G9: 0 | H9: 0 | I9: 0 | J9: 0 | K9: 0 | L9: 0 | M9: 0 | N9: 0 | O9: 0 | P9: {=SUM(LARGE(D9:O9,{1;2;3;4;5;6;7;8}))} -> 400 | Q9: {=SUM(LARGE(CHOOSE({1,2,3,4,5,6,7,8,9,10}, D9, E9, F9, G9, H9, I9, J9, K9, L9, 250), {1,2,3,4,5,6,7}))} -> 650
B10: =ROW() - ROW($B$6) + 1 -> 5 | C10: David Linares Ramos | D10: =IFERROR(VLOOKUP($C10,'Etapa 1 Senior'!$E$3:$G$83,3,FALSE),0) -> 0 | E10: =IFERROR(VLOOKUP($C10,'Etapa 2 Senior'!$E$3:$G$83,3,FALSE),0) -> 215 | F10: 0 | G10: 0 | H10: 0 | I10: 0 | J10: 0 | K10: 0 | L10: 0 | M10: 0 | N10: 0 | O10: 0 | P10: {=SUM(LARGE(D10:O10,{1;2;3;4;5;6;7;8}))} -> 215 | Q10: {=SUM(LARGE(CHOOSE({1,2,3,4,5,6,7,8,9,10}, D10, E10, F10, G10, H10, I10, J10, K10, L10, 250), {1,2,3,4,5,6,7}))} -> 465
B11: =ROW() - ROW($B$6) + 1 -> 6 | C11: Giacomo Bonacini | D11: =IFERROR(VLOOKUP($C11,'Etapa 1 Senior'!$E$3:$G$83,3,FALSE),0) -> 0 | E11: =IFERROR(VLOOKUP($C11,'Etapa 2 Senior'!$E$3:$G$83,3,FALSE),0) -> 180 | F11: 0 | G11: 0 | H11: 0 | I11: 0 | J11: 0 | K11: 0 | L11: 0 | M11: 0 | N11: 0 | O11: 0 | P11: {=SUM(LARGE(D11:O11,{1;2;3;4;5;6;7;8}))} -> 180 | Q11: {=SUM(LARGE(CHOOSE({1,2,3,4,5,6,7,8,9,10}, D11, E11, F11, G11, H11, I11, J11, K11, L11, 250), {1,2,3,4,5,6,7}))} -> 430
B12: =ROW() - ROW($B$6) + 1 -> 7 | C12: Jorge Santiago Buqueras | D12: =IFERROR(VLOOKUP($C12,'Etapa 1 Senior'!$E$3:$G$83,3,FALSE),0) -> 0 | E12: =IFERROR(VLOOKUP($C12,'Etapa 2 Senior'!$E$3:$G$83,3,FALSE),0) -> 0 | F12: 0 | G12: 0 | H12: 0 | I12: 0 | J12: 0 | K12: 0 | L12: 0 | M12: 0 | N12: 0 | O12: 0 | P12: {=SUM(LARGE(D12:O12,{1;2;3;4;5;6;7;8}))} -> 0 | Q12: {=SUM(LARGE(CHOOSE({1,2,3,4,5,6,7,8,9,10}, D12, E12, F12, G12, H12, I12, J12, K12, L12, 250), {1,2,3,4,5,6,7}))} -> 250
B13: =ROW() - ROW($B$6) + 1 -> 8 | C13: Chema🐗🐗 Martínez Guillamon | D13: =IFERROR(VLOOKUP($C13,'Etapa 1 Senior'!$E$3:$G$83,3,FALSE),0) -> 0 | E13: =IFERROR(VLOOKUP($C13,'Etapa 2 Senior'!$E$3:$G$83,3,FALSE),0) -> 0 | F13: 0 | G13: 0 | H13: 0 | I13: 0 | J13: 0 | K13: 0 | L13: 0 | M13: 0 | N13: 0 | O13: 0 | P13: {=SUM(LARGE(D13:O13,{1;2;3;4;5;6;7;8}))} -> 0 | Q13: {=SUM(LARGE(CHOOSE({1,2,3,4,5,6,7,8,9,10}, D13, E13, F13, G13, H13, I13, J13, K13, L13, 250), {1,2,3,4,5,6,7}))} -> 250
B14: =ROW() - ROW($B$6) + 1 -> 9 | C14: JuanRa Perez | D14: =IFERROR(VLOOKUP($C14,'Etapa 1 Senior'!$E$3:$G$83,3,FALSE),0) -> 0 | E14: =IFERROR(VLOOKUP($C14,'Etapa 2 Senior'!$E$3:$G$83,3,FALSE),0) -> 0 | F14: 0 | G14: 0 | H14: 0 | I14: 0 | J14: 0 | K14: 0 | L14: 0 | M14: 0 | N14: 0 | O14: 0 | P14: {=SUM(LARGE(D14:O14,{1;2;3;4;5;6;7;8}))} -> 0 | Q14: {=SUM(LARGE(CHOOSE({1,2,3,4,5,6,7,8,9,10}, D14, E14, F14, G14, H14, I14, J14, K14, L14, 250), {1,2,3,4,5,6,7}))} -> 250
B15: =ROW() - ROW($B$6) + 1 -> 10 | C15: Xavi Leiva Cañada | D15: =IFERROR(VLOOKUP($C15,'Etapa 1 Senior'!$E$3:$G$83,3,FALSE),0) -> 0 | E15: =IFERROR(VLOOKUP($C15,'Etapa 2 Senior'!$E$3:$G$83,3,FALSE),0) -> 0 | F15: 0 | G15: 0 | H15: 0 | I15: 0 | J15: 0 | K15: 0 | L15: 0 | M15: 0 | N15: 0 | O15: 0 | P15: {=SUM(LARGE(D15:O15,{1;2;3;4;5;6;7;8}))} -> 0 | Q15: {=SUM(LARGE(CHOOSE({1,2,3,4,5,6,7,8,9,10}, D15, E15, F15, G15, H15, I15, J15, K15, L15, 250), {1,2,3,4,5,6,7}))} -> 250
B16: =ROW() - ROW($B$6) + 1 -> 11 | C16: Eduardo Martin Rodriguez | D16: =IFERROR(VLOOKUP($C16,'Etapa 1 Senior'!$E$3:$G$83,3,FALSE),0) -> 0 | E16: =IFERROR(VLOOKUP($C16,'Etapa 2 Senior'!$E$3:$G$83,3,FALSE),0) -> 0 | F16: 0 | G16: 0 | H16: 0 | I16: 0 | J16: 0 | K16: 0 | L16: 0 | M16: 0 | N16: 0 | O16: 0 | P16: {=SUM(LARGE(D16:O16,{1;2;3;4;5;6;7;8}))} -> 0 | Q16: {=SUM(LARGE(CHOOSE({1,2,3,4,5,6,7,8,9,10}, D16, E16, F16, G16, H16, I16, J16, K16, L16, 250), {1,2,3,4,5,6,7}))} -> 250
B17: =ROW() - ROW($B$6) + 1 -> 12 | C17: Alberto Leiva cañada | D17: =IFERROR(VLOOKUP($C17,'Etapa 1 Senior'!$E$3:$G$83,3,FALSE),0) -> 0 | E17: =IFERROR(VLOOKUP($C17,'Etapa 2 Senior'!$E$3:$G$83,3,FALSE),0) -> 0 | F17: 0 | G17: 0 | H17: 0 | I17: 0 | J17: 0 | K17: 0 | L17: 0 | M17: 0 | N17: 0 | O17: 0 | P17: {=SUM(LARGE(D17:O17,{1;2;3;4;5;6;7;8}))} -> 0 | Q17: {=SUM(LARGE(CHOOSE({1,2,3,4,5,6,7,8,9,10}, D17, E17, F17, G17, H17, I17, J17, K17, L17, 250), {1,2,3,4,5,6,7}))} -> 250
B18: =ROW() - ROW($B$6) + 1 -> 13 | C18: Alberto Salazar Fernández | D18: =IFERROR(VLOOKUP($C18,'Etapa 1 Senior'!$E$3:$G$83,3,FALSE),0) -> 0 | E18: =IFERROR(VLOOKUP($C18,'Etapa 2 Senior'!$E$3:$G$83,3,FALSE),0) -> 0 | F18: 0 | G18: 0 | H18: 0 | I18: 0 | J18: 0 | K18: 0 | L18: 0 | M18: 0 | N18: 0 | O18: 0 | P18: {=SUM(LARGE(D18:O18,{1;2;3;4;5;6;7;8}))} -> 0 | Q18: {=SUM(LARGE(CHOOSE({1,2,3,4,5,6,7,8,9,10}, D18, E18, F18, G18, H18, I18, J18, K18, L18, 250), {1,2,3,4,5,6,7}))} -> 250
B19: =ROW() - ROW($B$6) + 1 -> 14 | C19: benito reyes gonzalez | D19: =IFERROR(VLOOKUP($C19,'Etapa 1 Senior'!$E$3:$G$83,3,FALSE),0) -> 0 | E19: =IFERROR(VLOOKUP($C19,'Etapa 2 Senior'!$E$3:$G$83,3,FALSE),0) -> 0 | F19: 0 | G19: 0 | H19: 0 | I19: 0 | J19: 0 | K19: 0 | L19: 0 | M19: 0 | N19: 0 | O19: 0 | P19: {=SUM(LARGE(D19:O19,{1;2;3;4;5;6;7;8}))} -> 0 | Q19: {=SUM(LARGE(CHOOSE({1,2,3,4,5,6,7,8,9,10}, D19, E19, F19, G19, H19, I19, J19, K19, L19, 250), {1,2,3,4,5,6,7}))} -> 250
B20: =ROW() - ROW($B$6) + 1 -> 15 | C20: David Tellez Viana | D20: =IFERROR(VLOOKUP($C20,'Etapa 1 Senior'!$E$3:$G$83,3,FALSE),0) -> 0 | E20: =IFERROR(VLOOKUP($C20,'Etapa 2 Senior'!$E$3:$G$83,3,FALSE),0) -> 0 | F20: 0 | G20: 0 | H20: 0 | I20: 0 | J20: 0 | K20: 0 | L20: 0 | M20: 0 | N20: 0 | O20: 0 | P20: {=SUM(LARGE(D20:O20,{1;2;3;4;5;6;7;8}))} -> 0 | Q20: {=SUM(LARGE(CHOOSE({1,2,3,4,5,6,7,8,9,10}, D20, E20, F20, G20, H20, I20, J20, K20, L20, 250), {1,2,3,4,5,6,7}))} -> 250
... B49: =ROW() - ROW($B$6) + 1 -> 44 | C49: guillermo Beroy Álvarez | D49: =IFERROR(VLOOKUP($C49,'Etapa 1 Senior'!$E$3:$G$83,3,FALSE),0) -> 0 | E49: =IFERROR(VLOOKUP($C49,'Etapa 2 Senior'!$E$3:$G$83,3,FALSE),0) -> 0 | F49: 0 | G49: 0 | H49: 0 | I49: 0 | J49: 0 | K49: 0 | L49: 0 | M49: 0 | N49: 0 | O49: 0 | P49: {=SUM(LARGE(D49:O49,{1;2;3;4;5;6;7;8}))} -> 0 | Q49: {=SUM(LARGE(CHOOSE({1,2,3,4,5,6,7,8,9,10}, D49, E49, F49, G49, H49, I49, J49, K49, L49, 250), {1,2,3,4,5,6,7}))} -> 250

Sheet Ranking Rookie
B3: RANKING ROOKIE
B5: Posicion | C5: FOOTGOLFER NICKNAME | D5: Etapa 1 | E5: Etapa 2 | F5: Etapa 3 | G5: Etapa 4 | H5: Etapa 5 | I5: Etapa 6 | J5: Etapa 7 | K5: Etapa 8 | L5: Etapa 9 | M5: Etapa 10 | N5: Etapa 11 | O5: Etapa 12 | P5: Total | Q5: Maxima puntuacion posible
B6: =ROW() - ROW($B$6) + 1 -> 1 | C6: Sergi Pahisa | D6: =IFERROR(VLOOKUP($C6,'Etapa 1 Rookie'!$E$3:$G$83,3,FALSE),0) -> 230 | E6: =IFERROR(VLOOKUP($C6,'Etapa 2 Rookie'!$E$3:$G$83,3,FALSE),0) -> 250 | F6: 0 | G6: 0 | H6: 0 | I6: 0 | J6: 0 | K6: 0 | L6: 0 | M6: 0 | N6: 0 | O6: 0 | P6: {=SUM(LARGE(D6:O6,{1;2;3;4;5;6;7;8}))} -> 480 | Q6: {=SUM(LARGE(CHOOSE({1,2,3,4,5,6,7,8,9,10}, D6, E6, F6, G6, H6, I6, J6, K6, L6, 250), {1,2,3,4,5,6,7}))} -> 730 | U6: Primero | V6: jorge
B7: =ROW() - ROW($B$6) + 1 -> 2 | C7: Xavi Leiva Cañada | D7: =IFERROR(VLOOKUP($C7,'Etapa 1 Rookie'!$E$3:$G$83,3,FALSE),0) -> 250 | E7: =IFERROR(VLOOKUP($C7,'Etapa 2 Rookie'!$E$3:$G$83,3,FALSE),0) -> 215 | F7: 0 | G7: 0 | H7: 0 | I7: 0 | J7: 0 | K7: 0 | L7: 0 | M7: 0 | N7: 0 | O7: 0 | P7: {=SUM(LARGE(D7:O7,{1;2;3;4;5;6;7;8}))} -> 465 | Q7: {=SUM(LARGE(CHOOSE({1,2,3,4,5,6,7,8,9,10}, D7, E7, F7, G7, H7, I7, J7, K7, L7, 250), {1,2,3,4,5,6,7}))} -> 715 | U7: Segundo | V7: Chema
B8: =ROW() - ROW($B$6) + 1 -> 3 | C8: Alberto Leiva cañada | D8: =IFERROR(VLOOKUP($C8,'Etapa 1 Rookie'!$E$3:$G$83,3,FALSE),0) -> 215 | E8: =IFERROR(VLOOKUP($C8,'Etapa 2 Rookie'!$E$3:$G$83,3,FALSE),0) -> 160 | F8: 0 | G8: 0 | H8: 0 | I8: 0 | J8: 0 | K8: 0 | L8: 0 | M8: 0 | N8: 0 | O8: 0 | P8: {=SUM(LARGE(D8:O8,{1;2;3;4;5;6;7;8}))} -> 375 | Q8: {=SUM(LARGE(CHOOSE({1,2,3,4,5,6,7,8,9,10}, D8, E8, F8, G8, H8, I8, J8, K8, L8, 250), {1,2,3,4,5,6,7}))} -> 625 | U8: Tercero | V8: JuanRa
B9: =ROW() - ROW($B$6) + 1 -> 4 | C9: Mario Morón Sancho | D9: =IFERROR(VLOOKUP($C9,'Etapa 1 Rookie'!$E$3:$G$83,3,FALSE),0) -> 185 | E9: =IFERROR(VLOOKUP($C9,'Etapa 2 Rookie'!$E$3:$G$83,3,FALSE),0) -> 170 | F9: 0 | G9: 0 | H9: 0 | I9: 0 | J9: 0 | K9: 0 | L9: 0 | M9: 0 | N9: 0 | O9: 0 | P9: {=SUM(LARGE(D9:O9,{1;2;3;4;5;6;7;8}))} -> 355 | Q9: {=SUM(LARGE(CHOOSE({1,2,3,4,5,6,7,8,9,10}, D9, E9, F9, G9, H9, I9, J9, K9, L9, 250), {1,2,3,4,5,6,7}))} -> 605
B10: =ROW() - ROW($B$6) + 1 -> 5 | C10: ivan luengo robles | D10: =IFERROR(VLOOKUP($C10,'Etapa 1 Rookie'!$E$3:$G$83,3,FALSE),0) -> 165 | E10: =IFERROR(VLOOKUP($C10,'Etapa 2 Rookie'!$E$3:$G$83,3,FALSE),0) -> 190 | F10: 0 | G10: 0 | H10: 0 | I10: 0 | J10: 0 | K10: 0 | L10: 0 | M10: 0 | N10: 0 | O10: 0 | P10: {=SUM(LARGE(D10:O10,{1;2;3;4;5;6;7;8}))} -> 355 | Q10: {=SUM(LARGE(CHOOSE({1,2,3,4,5,6,7,8,9,10}, D10, E10, F10, G10, H10, I10, J10, K10, L10, 250), {1,2,3,4,5,6,7}))} -> 605
B11: =ROW() - ROW($B$6) + 1 -> 6 | C11: Raúl Linares Ramos | D11: =IFERROR(VLOOKUP($C11,'Etapa 1 Rookie'!$E$3:$G$83,3,FALSE),0) -> 165 | E11: =IFERROR(VLOOKUP($C11,'Etapa 2 Rookie'!$E$3:$G$83,3,FALSE),0) -> 180 | F11: 0 | G11: 0 | H11: 0 | I11: 0 | J11: 0 | K11: 0 | L11: 0 | M11: 0 | N11: 0 | O11: 0 | P11: {=SUM(LARGE(D11:O11,{1;2;3;4;5;6;7;8}))} -> 345 | Q11: {=SUM(LARGE(CHOOSE({1,2,3,4,5,6,7,8,9,10}, D11, E11, F11, G11, H11, I11, J11, K11, L11, 250), {1,2,3,4,5,6,7}))} -> 595
B12: 10 | C12: Daniel Abril Amador | D12: =IFERROR(VLOOKUP($C12,'Etapa 1 Rookie'!$E$3:$G$83,3,FALSE),0) -> 140 | E12: =IFERROR(VLOOKUP($C12,'Etapa 2 Rookie'!$E$3:$G$83,3,FALSE),0) -> 200 | F12: 0 | G12: 0 | H12: 0 | I12: 0 | J12: 0 | K12: 0 | L12: 0 | M12: 0 | N12: 0 | O12: 0 | P12: {=SUM(LARGE(D12:O12,{1;2;3;4;5;6;7;8}))} -> 340 | Q12: {=SUM(LARGE(CHOOSE({1,2,3,4,5,6,7,8,9,10}, D12, E12, F12, G12, H12, I12, J12, K12, L12, 250), {1,2,3,4,5,6,7}))} -> 590
B13: =ROW() - ROW($B$6) + 1 -> 8 | C13: David Tellez Viana | D13: =IFERROR(VLOOKUP($C13,'Etapa 1 Rookie'!$E$3:$G$83,3,FALSE),0) -> 200 | E13: =IFERROR(VLOOKUP($C13,'Etapa 2 Rookie'!$E$3:$G$83,3,FALSE),0) -> 120 | F13: 0 | G13: 0 | H13: 0 | I13: 0 | J13: 0 | K13: 0 | L13: 0 | M13: 0 | N13: 0 | O13: 0 | P13: {=SUM(LARGE(D13:O13,{1;2;3;4;5;6;7;8}))} -> 320 | Q13: {=SUM(LARGE(CHOOSE({1,2,3,4,5,6,7,8,9,10}, D13, E13, F13, G13, H13, I13, J13, K13, L13, 250), {1,2,3,4,5,6,7}))} -> 570
B14: 9 | C14: Gustavo Verse | D14: =IFERROR(VLOOKUP($C14,'Etapa 1 Rookie'!$E$3:$G$83,3,FALSE),0) -> 150 | E14: =IFERROR(VLOOKUP($C14,'Etapa 2 Rookie'!$E$3:$G$83,3,FALSE),0) -> 130 | F14: 0 | G14: 0 | H14: 0 | I14: 0 | J14: 0 | K14: 0 | L14: 0 | M14: 0 | N14: 0 | O14: 0 | P14: {=SUM(LARGE(D14:O14,{1;2;3;4;5;6;7;8}))} -> 280 | Q14: {=SUM(LARGE(CHOOSE({1,2,3,4,5,6,7,8,9,10}, D14, E14, F14, G14, H14, I14, J14, K14, L14, 250), {1,2,3,4,5,6,7}))} -> 530
B15: =ROW() - ROW($B$6) + 1 -> 10 | C15: Eduardo Martin Rodriguez | D15: =IFERROR(VLOOKUP($C15,'Etapa 1 Rookie'!$E$3:$G$83,3,FALSE),0) -> 0 | E15: =IFERROR(VLOOKUP($C15,'Etapa 2 Rookie'!$E$3:$G$83,3,FALSE),0) -> 230 | F15: 0 | G15: 0 | H15: 0 | I15: 0 | J15: 0 | K15: 0 | L15: 0 | M15: 0 | N15: 0 | O15: 0 | P15: {=SUM(LARGE(D15:O15,{1;2;3;4;5;6;7;8}))} -> 230 | Q15: {=SUM(LARGE(CHOOSE({1,2,3,4,5,6,7,8,9,10}, D15, E15, F15, G15, H15, I15, J15, K15, L15, 250), {1,2,3,4,5,6,7}))} -> 480
B16: 11 | C16: Juan Medina | D16: =IFERROR(VLOOKUP($C16,'Etapa 1 Rookie'!$E$3:$G$83,3,FALSE),0) -> 130 | E16: =IFERROR(VLOOKUP($C16,'Etapa 2 Rookie'!$E$3:$G$83,3,FALSE),0) -> 95 | F16: 0 | G16: 0 | H16: 0 | I16: 0 | J16: 0 | K16: 0 | L16: 0 | M16: 0 | N16: 0 | O16: 0 | P16: {=SUM(LARGE(D16:O16,{1;2;3;4;5;6;7;8}))} -> 225 | Q16: {=SUM(LARGE(CHOOSE({1,2,3,4,5,6,7,8,9,10}, D16, E16, F16, G16, H16, I16, J16, K16, L16, 250), {1,2,3,4,5,6,7}))} -> 475
B17: 12 | C17: Luca Rubinacci | D17: =IFERROR(VLOOKUP($C17,'Etapa 1 Rookie'!$E$3:$G$83,3,FALSE),0) -> 120 | E17: =IFERROR(VLOOKUP($C17,'Etapa 2 Rookie'!$E$3:$G$83,3,FALSE),0) -> 100 | F17: 0 | G17: 0 | H17: 0 | I17: 0 | J17: 0 | K17: 0 | L17: 0 | M17: 0 | N17: 0 | O17: 0 | P17: {=SUM(LARGE(D17:O17,{1;2;3;4;5;6;7;8}))} -> 220 | Q17: {=SUM(LARGE(CHOOSE({1,2,3,4,5,6,7,8,9,10}, D17, E17, F17, G17, H17, I17, J17, K17, L17, 250), {1,2,3,4,5,6,7}))} -> 470
B18: =ROW() - ROW($B$7) + 1 -> 12 | C18: Gastón Masuck Cardozo | D18: =IFERROR(VLOOKUP($C18,'Etapa 1 Rookie'!$E$3:$G$83,3,FALSE),0) -> 185 | E18: =IFERROR(VLOOKUP($C18,'Etapa 2 Rookie'!$E$3:$G$83,3,FALSE),0) -> 0 | F18: 0 | G18: 0 | H18: 0 | I18: 0 | J18: 0 | K18: 0 | L18: 0 | M18: 0 | N18: 0 | O18: 0 | P18: {=SUM(LARGE(D18:O18,{1;2;3;4;5;6;7;8}))} -> 185 | Q18: {=SUM(LARGE(CHOOSE({1,2,3,4,5,6,7,8,9,10}, D18, E18, F18, G18, H18, I18, J18, K18, L18, 250), {1,2,3,4,5,6,7}))} -> 435
B19: =ROW() - ROW($B$6) + 1 -> 14 | C19: Marc Company Salvat | D19: =IFERROR(VLOOKUP($C19,'Etapa 1 Rookie'!$E$3:$G$83,3,FALSE),0) -> 0 | E19: =IFERROR(VLOOKUP($C19,'Etapa 2 Rookie'!$E$3:$G$83,3,FALSE),0) -> 145 | F19: 0 | G19: 0 | H19: 0 | I19: 0 | J19: 0 | K19: 0 | L19: 0 | M19: 0 | N19: 0 | O19: 0 | P19: {=SUM(LARGE(D19:O19,{1;2;3;4;5;6;7;8}))} -> 145 | Q19: {=SUM(LARGE(CHOOSE({1,2,3,4,5,6,7,8,9,10}, D19, E19, F19, G19, H19, I19, J19, K19, L19, 250), {1,2,3,4,5,6,7}))} -> 395
B20: =ROW() - ROW($B$7) + 1 -> 14 | C20: Erik Mata | D20: =IFERROR(VLOOKUP($C20,'Etapa 1 Rookie'!$E$3:$G$83,3,FALSE),0) -> 0 | E20: =IFERROR(VLOOKUP($C20,'Etapa 2 Rookie'!$E$3:$G$83,3,FALSE),0) -> 145 | F20: 0 | G20: 0 | H20: 0 | I20: 0 | J20: 0 | K20: 0 | L20: 0 | M20: 0 | N20: 0 | O20: 0 | P20: {=SUM(LARGE(D20:O20,{1;2;3;4;5;6;7;8}))} -> 145 | Q20: {=SUM(LARGE(CHOOSE({1,2,3,4,5,6,7,8,9,10}, D20, E20, F20, G20, H20, I20, J20, K20, L20, 250), {1,2,3,4,5,6,7}))} -> 395
B21: =ROW() - ROW($B$7) + 1 -> 15 | C21: Jordi Ortega López | D21: =IFERROR(VLOOKUP($C21,'Etapa 1 Rookie'!$E$3:$G$83,3,FALSE),0) -> 0 | E21: =IFERROR(VLOOKUP($C21,'Etapa 2 Rookie'!$E$3:$G$83,3,FALSE),0) -> 110 | F21: 0 | G21: 0 | H21: 0 | I21: 0 | J21: 0 | K21: 0 | L21: 0 | M21: 0 | N21: 0 | O21: 0 | P21: {=SUM(LARGE(D21:O21,{1;2;3;4;5;6;7;8}))} -> 110 | Q21: {=SUM(LARGE(CHOOSE({1,2,3,4,5,6,7,8,9,10}, D21, E21, F21, G21, H21, I21, J21, K21, L21, 250), {1,2,3,4,5,6,7}))} -> 360
B22: =ROW() - ROW($B$6) + 1 -> 17 | C22: Olivier TRESSENS | D22: =IFERROR(VLOOKUP($C22,'Etapa 1 Rookie'!$E$3:$G$83,3,FALSE),0) -> 0 | E22: =IFERROR(VLOOKUP($C22,'Etapa 2 Rookie'!$E$3:$G$83,3,FALSE),0) -> 0 | F22: 0 | G22: 0 | H22: 0 | I22: 0 | J22: 0 | K22: 0 | L22: 0 | M22: 0 | N22: 0 | O22: 0 | P22: {=SUM(LARGE(D22:O22,{1;2;3;4;5;6;7;8}))} -> 0 | Q22: {=SUM(LARGE(CHOOSE({1,2,3,4,5,6,7,8,9,10}, D22, E22, F22, G22, H22, I22, J22, K22, L22, 250), {1,2,3,4,5,6,7}))} -> 250
B23: =ROW() - ROW($B$6) + 1 -> 18 | C23: Fernando Martínez Guillamón | D23: =IFERROR(VLOOKUP($C23,'Etapa 1 Rookie'!$E$3:$G$83,3,FALSE),0) -> 0 | E23: =IFERROR(VLOOKUP($C23,'Etapa 2 Rookie'!$E$3:$G$83,3,FALSE),0) -> 0 | F23: 0 | G23: 0 | H23: 0 | I23: 0 | J23: 0 | K23: 0 | L23: 0 | M23: 0 | N23: 0 | O23: 0 | P23: {=SUM(LARGE(D23:O23,{1;2;3;4;5;6;7;8}))} -> 0 | Q23: {=SUM(LARGE(CHOOSE({1,2,3,4,5,6,7,8,9,10}, D23, E23, F23, G23, H23, I23, J23, K23, L23, 250), {1,2,3,4,5,6,7}))} -> 250
B24: 1 | C24: Jorge Santiago Buqueras | D24: =IFERROR(VLOOKUP($C24,'Etapa 1 Rookie'!$E$3:$G$83,3,FALSE),0) -> 0 | E24: =IFERROR(VLOOKUP($C24,'Etapa 2 Rookie'!$E$3:$G$83,3,FALSE),0) -> 0 | F24: 0 | G24: 0 | H24: 0 | I24: 0 | J24: 0 | K24: 0 | L24: 0 | M24: 0 | N24: 0 | O24: 0 | P24: {=SUM(LARGE(D24:O24,{1;2;3;4;5;6;7;8}))} -> 0 | Q24: {=SUM(LARGE(CHOOSE({1,2,3,4,5,6,7,8,9,10}, D24, E24, F24, G24, H24, I24, J24, K24, L24, 250), {1,2,3,4,5,6,7}))} -> 250
B25: =ROW() - ROW($B$6) + 1 -> 20 | C25: Chema🐗🐗 Martínez Guillamon | D25: =IFERROR(VLOOKUP($C25,'Etapa 1 Rookie'!$E$3:$G$83,3,FALSE),0) -> 0 | E25: =IFERROR(VLOOKUP($C25,'Etapa 2 Rookie'!$E$3:$G$83,3,FALSE),0) -> 0 | F25: 0 | G25: 0 | H25: 0 | I25: 0 | J25: 0 | K25: 0 | L25: 0 | M25: 0 | N25: 0 | O25: 0 | P25: {=SUM(LARGE(D25:O25,{1;2;3;4;5;6;7;8}))} -> 0 | Q25: {=SUM(LARGE(CHOOSE({1,2,3,4,5,6,7,8,9,10}, D25, E25, F25, G25, H25, I25, J25, K25, L25, 250), {1,2,3,4,5,6,7}))} -> 250
B26: =ROW() - ROW($B$6) + 1 -> 21 | C26: JuanRa Perez | D26: =IFERROR(VLOOKUP($C26,'Etapa 1 Rookie'!$E$3:$G$83,3,FALSE),0) -> 0 | E26: =IFERROR(VLOOKUP($C26,'Etapa 2 Rookie'!$E$3:$G$83,3,FALSE),0) -> 0 | F26: 0 | G26: 0 | H26: 0 | I26: 0 | J26: 0 | K26: 0 | L26: 0 | M26: 0 | N26: 0 | O26: 0 | P26: {=SUM(LARGE(D26:O26,{1;2;3;4;5;6;7;8}))} -> 0 | Q26: {=SUM(LARGE(CHOOSE({1,2,3,4,5,6,7,8,9,10}, D26, E26, F26, G26, H26, I26, J26, K26, L26, 250), {1,2,3,4,5,6,7}))} -> 250
B27: =ROW() - ROW($B$6) + 1 -> 22 | C27: Alberto Salazar Fernández | D27: =IFERROR(VLOOKUP($C27,'Etapa 1 Rookie'!$E$3:$G$83,3,FALSE),0) -> 0 | E27: =IFERROR(VLOOKUP($C27,'Etapa 2 Rookie'!$E$3:$G$83,3,FALSE),0) -> 0 | F27: 0 | G27: 0 | H27: 0 | I27: 0 | J27: 0 | K27: 0 | L27: 0 | M27: 0 | N27: 0 | O27: 0 | P27: {=SUM(LARGE(D27:O27,{1;2;3;4;5;6;7;8}))} -> 0 | Q27: {=SUM(LARGE(CHOOSE({1,2,3,4,5,6,7,8,9,10}, D27, E27, F27, G27, H27, I27, J27, K27, L27, 250), {1,2,3,4,5,6,7}))} -> 250
B28: =ROW() - ROW($B$6) + 1 -> 23 | C28: benito reyes gonzalez | D28: =IFERROR(VLOOKUP($C28,'Etapa 1 Rookie'!$E$3:$G$83,3,FALSE),0) -> 0 | E28: =IFERROR(VLOOKUP($C28,'Etapa 2 Rookie'!$E$3:$G$83,3,FALSE),0) -> 0 | F28: 0 | G28: 0 | H28: 0 | I28: 0 | J28: 0 | K28: 0 | L28: 0 | M28: 0 | N28: 0 | O28: 0 | P28: {=SUM(LARGE(D28:O28,{1;2;3;4;5;6;7;8}))} -> 0 | Q28: {=SUM(LARGE(CHOOSE({1,2,3,4,5,6,7,8,9,10}, D28, E28, F28, G28, H28, I28, J28, K28, L28, 250), {1,2,3,4,5,6,7}))} -> 250
B29: =ROW() - ROW($B$6) + 1 -> 24 | C29: David Linares Ramos | D29: =IFERROR(VLOOKUP($C29,'Etapa 1 Rookie'!$E$3:$G$83,3,FALSE),0) -> 0 | E29: =IFERROR(VLOOKUP($C29,'Etapa 2 Rookie'!$E$3:$G$83,3,FALSE),0) -> 0 | F29: 0 | G29: 0 | H29: 0 | I29: 0 | J29: 0 | K29: 0 | L29: 0 | M29: 0 | N29: 0 | O29: 0 | P29: {=SUM(LARGE(D29:O29,{1;2;3;4;5;6;7;8}))} -> 0 | Q29: {=SUM(LARGE(CHOOSE({1,2,3,4,5,6,7,8,9,10}, D29, E29, F29, G29, H29, I29, J29, K29, L29, 250), {1,2,3,4,5,6,7}))} -> 250
B30: =ROW() - ROW($B$6) + 1 -> 25 | C30: Jesús Pizarro Gonzálvez | D30: =IFERROR(VLOOKUP($C30,'Etapa 1 Rookie'!$E$3:$G$83,3,FALSE),0) -> 0 | E30: =IFERROR(VLOOKUP($C30,'Etapa 2 Rookie'!$E$3:$G$83,3,FALSE),0) -> 0 | F30: 0 | G30: 0 | H30: 0 | I30: 0 | J30: 0 | K30: 0 | L30: 0 | M30: 0 | N30: 0 | O30: 0 | P30: {=SUM(LARGE(D30:O30,{1;2;3;4;5;6;7;8}))} -> 0 | Q30: {=SUM(LARGE(CHOOSE({1,2,3,4,5,6,7,8,9,10}, D30, E30, F30, G30, H30, I30, J30, K30, L30, 250), {1,2,3,4,5,6,7}))} -> 250
B31: =ROW() - ROW($B$6) + 1 -> 26 | C31: Sergi Perez Vilar | D31: =IFERROR(VLOOKUP($C31,'Etapa 1 Rookie'!$E$3:$G$83,3,FALSE),0) -> 0 | E31: =IFERROR(VLOOKUP($C31,'Etapa 2 Rookie'!$E$3:$G$83,3,FALSE),0) -> 0 | F31: 0 | G31: 0 | H31: 0 | I31: 0 | J31: 0 | K31: 0 | L31: 0 | M31: 0 | N31: 0 | O31: 0 | P31: {=SUM(LARGE(D31:O31,{1;2;3;4;5;6;7;8}))} -> 0 | Q31: {=SUM(LARGE(CHOOSE({1,2,3,4,5,6,7,8,9,10}, D31, E31, F31, G31, H31, I31, J31, K31, L31, 250), {1,2,3,4,5,6,7}))} -> 250
B32: =ROW() - ROW($B$6) + 1 -> 27 | C32: Alex Trallero Domec | D32: =IFERROR(VLOOKUP($C32,'Etapa 1 Rookie'!$E$3:$G$83,3,FALSE),0) -> 0 | E32: =IFERROR(VLOOKUP($C32,'Etapa 2 Rookie'!$E$3:$G$83,3,FALSE),0) -> 0 | F32: 0 | G32: 0 | H32: 0 | I32: 0 | J32: 0 | K32: 0 | L32: 0 | M32: 0 | N32: 0 | O32: 0 | P32: {=SUM(LARGE(D32:O32,{1;2;3;4;5;6;7;8}))} -> 0 | Q32: {=SUM(LARGE(CHOOSE({1,2,3,4,5,6,7,8,9,10}, D32, E32, F32, G32, H32, I32, J32, K32, L32, 250), {1,2,3,4,5,6,7}))} -> 250
B33: =ROW() - ROW($B$6) + 1 -> 28 | C33: Nicola Perra | D33: =IFERROR(VLOOKUP($C33,'Etapa 1 Rookie'!$E$3:$G$83,3,FALSE),0) -> 0 | E33: =IFERROR(VLOOKUP($C33,'Etapa 2 Rookie'!$E$3:$G$83,3,FALSE),0) -> 0 | F33: 0 | G33: 0 | H33: 0 | I33: 0 | J33: 0 | K33: 0 | L33: 0 | M33: 0 | N33: 0 | O33: 0 | P33: {=SUM(LARGE(D33:O33,{1;2;3;4;5;6;7;8}))} -> 0 | Q33: {=SUM(LARGE(CHOOSE({1,2,3,4,5,6,7,8,9,10}, D33, E33, F33, G33, H33, I33, J33, K33, L33, 250), {1,2,3,4,5,6,7}))} -> 250
B34: =ROW() - ROW($B$6) + 1 -> 29 | C34: Marc Arrebola Sans | D34: =IFERROR(VLOOKUP($C34,'Etapa 1 Rookie'!$E$3:$G$83,3,FALSE),0) -> 0 | E34: =IFERROR(VLOOKUP($C34,'Etapa 2 Rookie'!$E$3:$G$83,3,FALSE),0) -> 0 | F34: 0 | G34: 0 | H34: 0 | I34: 0 | J34: 0 | K34: 0 | L34: 0 | M34: 0 | N34: 0 | O34: 0 | P34: {=SUM(LARGE(D34:O34,{1;2;3;4;5;6;7;8}))} -> 0 | Q34: {=SUM(LARGE(CHOOSE({1,2,3,4,5,6,7,8,9,10}, D34, E34, F34, G34, H34, I34, J34, K34, L34, 250), {1,2,3,4,5,6,7}))} -> 250
B35: =ROW() - ROW($B$6) + 1 -> 30 | C35: Sergi Nerin Velasco | D35: =IFERROR(VLOOKUP($C35,'Etapa 1 Rookie'!$E$3:$G$83,3,FALSE),0) -> 0 | E35: =IFERROR(VLOOKUP($C35,'Etapa 2 Rookie'!$E$3:$G$83,3,FALSE),0) -> 0 | F35: 0 | G35: 0 | H35: 0 | I35: 0 | J35: 0 | K35: 0 | L35: 0 | M35: 0 | N35: 0 | O35: 0 | P35: {=SUM(LARGE(D35:O35,{1;2;3;4;5;6;7;8}))} -> 0 | Q35: {=SUM(LARGE(CHOOSE({1,2,3,4,5,6,7,8,9,10}, D35, E35, F35, G35, H35, I35, J35, K35, L35, 250), {1,2,3,4,5,6,7}))} -> 250
B36: =ROW() - ROW($B$7) + 1 -> 30 | C36: Lucía Bernuz Culebras | D36: =IFERROR(VLOOKUP($C36,'Etapa 1 Rookie'!$E$3:$G$83,3,FALSE),0) -> 0 | E36: =IFERROR(VLOOKUP($C36,'Etapa 2 Rookie'!$E$3:$G$83,3,FALSE),0) -> 0 | F36: 0 | G36: 0 | H36: 0 | I36: 0 | J36: 0 | K36: 0 | L36: 0 | M36: 0 | N36: 0 | O36: 0 | P36: {=SUM(LARGE(D36:O36,{1;2;3;4;5;6;7;8}))} -> 0 | Q36: {=SUM(LARGE(CHOOSE({1,2,3,4,5,6,7,8,9,10}, D36, E36, F36, G36, H36, I36, J36, K36, L36, 250), {1,2,3,4,5,6,7}))} -> 250
B37: =ROW() - ROW($B$6) + 1 -> 32 | C37: Joan Torre Rodríguez | D37: =IFERROR(VLOOKUP($C37,'Etapa 1 Rookie'!$E$3:$G$83,3,FALSE),0) -> 0 | E37: =IFERROR(VLOOKUP($C37,'Etapa 2 Rookie'!$E$3:$G$83,3,FALSE),0) -> 0 | F37: 0 | G37: 0 | H37: 0 | I37: 0 | J37: 0 | K37: 0 | L37: 0 | M37: 0 | N37: 0 | O37: 0 | P37: {=SUM(LARGE(D37:O37,{1;2;3;4;5;6;7;8}))} -> 0 | Q37: {=SUM(LARGE(CHOOSE({1,2,3,4,5,6,7,8,9,10}, D37, E37, F37, G37, H37, I37, J37, K37, L37, 250), {1,2,3,4,5,6,7}))} -> 250
B38: =ROW() - ROW($B$6) + 1 -> 33 | C38: Giacomo Bonacini | D38: =IFERROR(VLOOKUP($C38,'Etapa 1 Rookie'!$E$3:$G$83,3,FALSE),0) -> 0 | E38: =IFERROR(VLOOKUP($C38,'Etapa 2 Rookie'!$E$3:$G$83,3,FALSE),0) -> 0 | F38: 0 | G38: 0 | H38: 0 | I38: 0 | J38: 0 | K38: 0 | L38: 0 | M38: 0 | N38: 0 | O38: 0 | P38: {=SUM(LARGE(D38:O38,{1;2;3;4;5;6;7;8}))} -> 0 | Q38: {=SUM(LARGE(CHOOSE({1,2,3,4,5,6,7,8,9,10}, D38, E38, F38, G38, H38, I38, J38, K38, L38, 250), {1,2,3,4,5,6,7}))} -> 250
B39: =ROW() - ROW($B$6) + 1 -> 34 | C39: Pau Blas Molina | D39: =IFERROR(VLOOKUP($C39,'Etapa 1 Rookie'!$E$3:$G$83,3,FALSE),0) -> 0 | E39: =IFERROR(VLOOKUP($C39,'Etapa 2 Rookie'!$E$3:$G$83,3,FALSE),0) -> 0 | F39: 0 | G39: 0 | H39: 0 | I39: 0 | J39: 0 | K39: 0 | L39: 0 | M39: 0 | N39: 0 | O39: 0 | P39: {=SUM(LARGE(D39:O39,{1;2;3;4;5;6;7;8}))} -> 0 | Q39: {=SUM(LARGE(CHOOSE({1,2,3,4,5,6,7,8,9,10}, D39, E39, F39, G39, H39, I39, J39, K39, L39, 250), {1,2,3,4,5,6,7}))} -> 250
B40: =ROW() - ROW($B$7) + 1 -> 34 | C40: David Cortés Segura | D40: =IFERROR(VLOOKUP($C40,'Etapa 1 Rookie'!$E$3:$G$83,3,FALSE),0) -> 0 | E40: =IFERROR(VLOOKUP($C40,'Etapa 2 Rookie'!$E$3:$G$83,3,FALSE),0) -> 0 | F40: 0 | G40: 0 | H40: 0 | I40: 0 | J40: 0 | K40: 0 | L40: 0 | M40: 0 | N40: 0 | O40: 0 | P40: {=SUM(LARGE(D40:O40,{1;2;3;4;5;6;7;8}))} -> 0 | Q40: {=SUM(LARGE(CHOOSE({1,2,3,4,5,6,7,8,9,10}, D40, E40, F40, G40, H40, I40, J40, K40, L40, 250), {1,2,3,4,5,6,7}))} -> 250
B41: =ROW() - ROW($B$7) + 1 -> 35 | C41: Aleix Martínez Muñoz | D41: =IFERROR(VLOOKUP($C41,'Etapa 1 Rookie'!$E$3:$G$83,3,FALSE),0) -> 0 | E41: =IFERROR(VLOOKUP($C41,'Etapa 2 Rookie'!$E$3:$G$83,3,FALSE),0) -> 0 | F41: 0 | G41: 0 | H41: 0 | I41: 0 | J41: 0 | K41: 0 | L41: 0 | M41: 0 | N41: 0 | O41: 0 | P41: {=SUM(LARGE(D41:O41,{1;2;3;4;5;6;7;8}))} -> 0 | Q41: {=SUM(LARGE(CHOOSE({1,2,3,4,5,6,7,8,9,10}, D41, E41, F41, G41, H41, I41, J41, K41, L41, 250), {1,2,3,4,5,6,7}))} -> 250
B42: =ROW() - ROW($B$6) + 1 -> 37 | C42: Albert Arrebola Sans | D42: =IFERROR(VLOOKUP($C42,'Etapa 1 Rookie'!$E$3:$G$83,3,FALSE),0) -> 0 | E42: =IFERROR(VLOOKUP($C42,'Etapa 2 Rookie'!$E$3:$G$83,3,FALSE),0) -> 0 | F42: 0 | G42: 0 | H42: 0 | I42: 0 | J42: 0 | K42: 0 | L42: 0 | M42: 0 | N42: 0 | O42: 0 | P42: {=SUM(LARGE(D42:O42,{1;2;3;4;5;6;7;8}))} -> 0 | Q42: {=SUM(LARGE(CHOOSE({1,2,3,4,5,6,7,8,9,10}, D42, E42, F42, G42, H42, I42, J42, K42, L42, 250), {1,2,3,4,5,6,7}))} -> 250
B43: =ROW() - ROW($B$6) + 1 -> 38 | C43: Guillem Moya Niubó | D43: =IFERROR(VLOOKUP($C43,'Etapa 1 Rookie'!$E$3:$G$83,3,FALSE),0) -> 0 | E43: =IFERROR(VLOOKUP($C43,'Etapa 2 Rookie'!$E$3:$G$83,3,FALSE),0) -> 0 | F43: 0 | G43: 0 | H43: 0 | I43: 0 | J43: 0 | K43: 0 | L43: 0 | M43: 0 | N43: 0 | O43: 0 | P43: {=SUM(LARGE(D43:O43,{1;2;3;4;5;6;7;8}))} -> 0 | Q43: {=SUM(LARGE(CHOOSE({1,2,3,4,5,6,7,8,9,10}, D43, E43, F43, G43, H43, I43, J43, K43, L43, 250), {1,2,3,4,5,6,7}))} -> 250
...

Sheet Ranking Plata
B4: RANKING PLATA
B6: Posicion | C6: FOOTGOLFER NICKNAME | D6: Etapa 1 | E6: Etapa 2 | F6: Etapa 3 | G6: Etapa 4 | H6: Etapa 5 | I6: Total | J6: Maxima puntuacion posible
B7: =ROW() - ROW($B$7) + 1 -> 1 | C7: Sergi Pahisa | D7: =IFERROR(VLOOKUP($C7,'Etapa 1 Plata'!$E$3:$G$102,3,FALSE),0) -> 250 | E7: =IFERROR(VLOOKUP($C7,'Etapa 2 Plata'!$E$3:$G$102,3,FALSE),0) -> 180 | F7: =IFERROR(VLOOKUP($C7,'Etapa 3 Plata'!$E$3:$G$102,3,FALSE),0) -> 230 | G7: =IFERROR(VLOOKUP($C7,'Etapa 4 Plata'!$E$3:$G$100,3,FALSE),0) -> 475 | H7: =IFERROR(VLOOKUP($C7,'Etapa 5 Plata'!$E$3:$G$100,3,FALSE),0) -> 200 | I7: {=SUM(LARGE(D7:H7,{1;2;3}))} -> 955 | J7: {=SUM(LARGE(CHOOSE({1,2,3,4,5},Tabla156[[#This Row],[Etapa 1]],Tabla156[[#This Row],[Etapa 2]],Tabla156[[#This Row],[Etapa 3]],Tabla156[[#This Row],[Etapa 4]],IF(Tabla156[[#This Row],[Etapa 5]]=0,250,Tabla156[[#This Row],[Etapa 5]])),{1,2,3}))} -> 955
B8: =ROW() - ROW($B$7) + 1 -> 2 | C8: ivan luengo robles | D8: =IFERROR(VLOOKUP($C8,'Etapa 1 Plata'!$E$3:$G$102,3,FALSE),0) -> 215 | E8: =IFERROR(VLOOKUP($C8,'Etapa 2 Plata'!$E$3:$G$102,3,FALSE),0) -> 215 | F8: =IFERROR(VLOOKUP($C8,'Etapa 3 Plata'!$E$3:$G$102,3,FALSE),0) -> 0 | G8: =IFERROR(VLOOKUP($C8,'Etapa 4 Plata'!$E$3:$G$100,3,FALSE),0) -> 500 | H8: =IFERROR(VLOOKUP($C8,'Etapa 5 Plata'!$E$3:$G$100,3,FALSE),0) -> 230 | I8: {=SUM(LARGE(D8:H8,{1;2;3}))} -> 945 | J8: {=SUM(LARGE(CHOOSE({1,2,3,4,5},Tabla156[[#This Row],[Etapa 1]],Tabla156[[#This Row],[Etapa 2]],Tabla156[[#This Row],[Etapa 3]],Tabla156[[#This Row],[Etapa 4]],IF(Tabla156[[#This Row],[Etapa 5]]=0,250,Tabla156[[#This Row],[Etapa 5]])),{1,2,3}))} -> 945 | M8: Primero | N8: Pahisa
B9: =ROW() - ROW($B$7) + 1 -> 3 | C9: Daniel Abril Amador | D9: =IFERROR(VLOOKUP($C9,'Etapa 1 Plata'!$E$3:$G$102,3,FALSE),0) -> 180 | E9: =IFERROR(VLOOKUP($C9,'Etapa 2 Plata'!$E$3:$G$102,3,FALSE),0) -> 170 | F9: =IFERROR(VLOOKUP($C9,'Etapa 3 Plata'!$E$3:$G$102,3,FALSE),0) -> 215 | G9: =IFERROR(VLOOKUP($C9,'Etapa 4 Plata'!$E$3:$G$100,3,FALSE),0) -> 450 | H9: =IFERROR(VLOOKUP($C9,'Etapa 5 Plata'!$E$3:$G$100,3,FALSE),0) -> 250 | I9: {=SUM(LARGE(D9:H9,{1;2;3}))} -> 915 | J9: {=SUM(LARGE(CHOOSE({1,2,3,4,5},Tabla156[[#This Row],[Etapa 1]],Tabla156[[#This Row],[Etapa 2]],Tabla156[[#This Row],[Etapa 3]],Tabla156[[#This Row],[Etapa 4]],IF(Tabla156[[#This Row],[Etapa 5]]=0,250,Tabla156[[#This Row],[Etapa 5]])),{1,2,3}))} -> 915 | M9: Segundo | N9: Ivan Luengo
B10: =ROW() - ROW($B$7) + 1 -> 4 | C10: Mario Morón Sancho | D10: =IFERROR(VLOOKUP($C10,'Etapa 1 Plata'!$E$3:$G$102,3,FALSE),0) -> 190 | E10: =IFERROR(VLOOKUP($C10,'Etapa 2 Plata'!$E$3:$G$102,3,FALSE),0) -> 230 | F10: =IFERROR(VLOOKUP($C10,'Etapa 3 Plata'!$E$3:$G$102,3,FALSE),0) -> 190 | G10: =IFERROR(VLOOKUP($C10,'Etapa 4 Plata'!$E$3:$G$100,3,FALSE),0) -> 425 | H10: =IFERROR(VLOOKUP($C10,'Etapa 5 Plata'!$E$3:$G$100,3,FALSE),0) -> 170 | I10: {=SUM(LARGE(D10:H10,{1;2;3}))} -> 845 | J10: {=SUM(LARGE(CHOOSE({1,2,3,4,5},Tabla156[[#This Row],[Etapa 1]],Tabla156[[#This Row],[Etapa 2]],Tabla156[[#This Row],[Etapa 3]],Tabla156[[#This Row],[Etapa 4]],IF(Tabla156[[#This Row],[Etapa 5]]=0,250,Tabla156[[#This Row],[Etapa 5]])),{1,2,3}))} -> 845 | M10: Tercero | N10: Daniel Abril
B11: =ROW() - ROW($B$7) + 1 -> 5 | C11: Marc Company Salvat | D11: =IFERROR(VLOOKUP($C11,'Etapa 1 Plata'!$E$3:$G$102,3,FALSE),0) -> 230 | E11: =IFERROR(VLOOKUP($C11,'Etapa 2 Plata'!$E$3:$G$102,3,FALSE),0) -> 140 | F11: =IFERROR(VLOOKUP($C11,'Etapa 3 Plata'!$E$3:$G$102,3,FALSE),0) -> 180 | G11: =IFERROR(VLOOKUP($C11,'Etapa 4 Plata'!$E$3:$G$100,3,FALSE),0) -> 400 | H11: =IFERROR(VLOOKUP($C11,'Etapa 5 Plata'!$E$3:$G$100,3,FALSE),0) -> 180 | I11: {=SUM(LARGE(D11:H11,{1;2;3}))} -> 810 | J11: {=SUM(LARGE(CHOOSE({1,2,3,4,5},Tabla156[[#This Row],[Etapa 1]],Tabla156[[#This Row],[Etapa 2]],Tabla156[[#This Row],[Etapa 3]],Tabla156[[#This Row],[Etapa 4]],IF(Tabla156[[#This Row],[Etapa 5]]=0,250,Tabla156[[#This Row],[Etapa 5]])),{1,2,3}))} -> 810 | N11: Ivan
B12: =ROW() - ROW($B$7) + 1 -> 6 | C12: Fernando Martínez Guillamón | D12: =IFERROR(VLOOKUP($C12,'Etapa 1 Plata'!$E$3:$G$102,3,FALSE),0) -> 170 | E12: =IFERROR(VLOOKUP($C12,'Etapa 2 Plata'!$E$3:$G$102,3,FALSE),0) -> 150 | F12: =IFERROR(VLOOKUP($C12,'Etapa 3 Plata'!$E$3:$G$102,3,FALSE),0) -> 160 | G12: =IFERROR(VLOOKUP($C12,'Etapa 4 Plata'!$E$3:$G$100,3,FALSE),0) -> 375 | H12: =IFERROR(VLOOKUP($C12,'Etapa 5 Plata'!$E$3:$G$100,3,FALSE),0) -> 190 | I12: {=SUM(LARGE(D12:H12,{1;2;3}))} -> 735 | J12: {=SUM(LARGE(CHOOSE({1,2,3,4,5},Tabla156[[#This Row],[Etapa 1]],Tabla156[[#This Row],[Etapa 2]],Tabla156[[#This Row],[Etapa 3]],Tabla156[[#This Row],[Etapa 4]],IF(Tabla156[[#This Row],[Etapa 5]]=0,250,Tabla156[[#This Row],[Etapa 5]])),{1,2,3}))} -> 735 | N12: Pahia
B13: =ROW() - ROW($B$7) + 1 -> 7 | C13: Gastón Masuck Cardozo | D13: =IFERROR(VLOOKUP($C13,'Etapa 1 Plata'!$E$3:$G$102,3,FALSE),0) -> 0 | E13: =IFERROR(VLOOKUP($C13,'Etapa 2 Plata'!$E$3:$G$102,3,FALSE),0) -> 250 | F13: =IFERROR(VLOOKUP($C13,'Etapa 3 Plata'!$E$3:$G$102,3,FALSE),0) -> 250 | G13: =IFERROR(VLOOKUP($C13,'Etapa 4 Plata'!$E$3:$G$100,3,FALSE),0) -> 0 | H13: =IFERROR(VLOOKUP($C13,'Etapa 5 Plata'!$E$3:$G$100,3,FALSE),0) -> 0 | I13: {=SUM(LARGE(D13:H13,{1;2;3}))} -> 500 | J13: {=SUM(LARGE(CHOOSE({1,2,3,4,5},Tabla156[[#This Row],[Etapa 1]],Tabla156[[#This Row],[Etapa 2]],Tabla156[[#This Row],[Etapa 3]],Tabla156[[#This Row],[Etapa 4]],IF(Tabla156[[#This Row],[Etapa 5]]=0,250,Tabla156[[#This Row],[Etapa 5]])),{1,2,3}))} -> 750 | N13: Morion
B14: =ROW() - ROW($B$7) + 1 -> 8 | C14: David Cortés Segura | D14: =IFERROR(VLOOKUP($C14,'Etapa 1 Plata'!$E$3:$G$102,3,FALSE),0) -> 0 | E14: =IFERROR(VLOOKUP($C14,'Etapa 2 Plata'!$E$3:$G$102,3,FALSE),0) -> 130 | F14: =IFERROR(VLOOKUP($C14,'Etapa 3 Plata'!$E$3:$G$102,3,FALSE),0) -> 170 | G14: =IFERROR(VLOOKUP($C14,'Etapa 4 Plata'!$E$3:$G$100,3,FALSE),0) -> 0 | H14: =IFERROR(VLOOKUP($C14,'Etapa 5 Plata'!$E$3:$G$100,3,FALSE),0) -> 150 | I14: {=SUM(LARGE(D14:H14,{1;2;3}))} -> 450 | J14: {=SUM(LARGE(CHOOSE({1,2,3,4,5},Tabla156[[#This Row],[Etapa 1]],Tabla156[[#This Row],[Etapa 2]],Tabla156[[#This Row],[Etapa 3]],Tabla156[[#This Row],[Etapa 4]],IF(Tabla156[[#This Row],[Etapa 5]]=0,250,Tabla156[[#This Row],[Etapa 5]])),{1,2,3}))} -> 450 | N14: Marc
